<mujoco model="cloth">
  <compiler angle="radian"/>

  <option timestep="0.001" tolerance="1e-06" integrator="implicitfast" solver="CG"/>

  <size memory="20M"/>

  <asset>
    <texture type="2d" name="cloth" file="textures/carpet.png"/>
    <material name="cloth" texture="cloth" texuniform="true" reflectance="0.2"/>
  </asset>

  <worldbody>
    <light pos="0 0 1.5" dir="0 0 -1"/>
    <body name="cloth_0" pos="-0.75 -0.75 0.1">
      <inertial pos="0 0 0" mass="0.00390625" diaginertia="6.51042e-08 6.51042e-08 6.51042e-08"/>
      <joint pos="0 0 0" axis="1 0 0" type="slide"/>
      <joint pos="0 0 0" axis="0 1 0" type="slide"/>
      <joint pos="0 0 0" axis="0 0 1" type="slide"/>
    </body>
    <body name="cloth_1" pos="-0.75 -0.65 0.1">
      <inertial pos="0 0 0" mass="0.00390625" diaginertia="6.51042e-08 6.51042e-08 6.51042e-08"/>
      <joint pos="0 0 0" axis="1 0 0" type="slide"/>
      <joint pos="0 0 0" axis="0 1 0" type="slide"/>
      <joint pos="0 0 0" axis="0 0 1" type="slide"/>
    </body>
    <body name="cloth_2" pos="-0.75 -0.55 0.1">
      <inertial pos="0 0 0" mass="0.00390625" diaginertia="6.51042e-08 6.51042e-08 6.51042e-08"/>
      <joint pos="0 0 0" axis="1 0 0" type="slide"/>
      <joint pos="0 0 0" axis="0 1 0" type="slide"/>
      <joint pos="0 0 0" axis="0 0 1" type="slide"/>
    </body>
    <body name="cloth_3" pos="-0.75 -0.45 0.1">
      <inertial pos="0 0 0" mass="0.00390625" diaginertia="6.51042e-08 6.51042e-08 6.51042e-08"/>
      <joint pos="0 0 0" axis="1 0 0" type="slide"/>
      <joint pos="0 0 0" axis="0 1 0" type="slide"/>
      <joint pos="0 0 0" axis="0 0 1" type="slide"/>
    </body>
    <body name="cloth_4" pos="-0.75 -0.35 0.1">
      <inertial pos="0 0 0" mass="0.00390625" diaginertia="6.51042e-08 6.51042e-08 6.51042e-08"/>
      <joint pos="0 0 0" axis="1 0 0" type="slide"/>
      <joint pos="0 0 0" axis="0 1 0" type="slide"/>
      <joint pos="0 0 0" axis="0 0 1" type="slide"/>
    </body>
    <body name="cloth_5" pos="-0.75 -0.25 0.1">
      <inertial pos="0 0 0" mass="0.00390625" diaginertia="6.51042e-08 6.51042e-08 6.51042e-08"/>
      <joint pos="0 0 0" axis="1 0 0" type="slide"/>
      <joint pos="0 0 0" axis="0 1 0" type="slide"/>
      <joint pos="0 0 0" axis="0 0 1" type="slide"/>
    </body>
    <body name="cloth_6" pos="-0.75 -0.15 0.1">
      <inertial pos="0 0 0" mass="0.00390625" diaginertia="6.51042e-08 6.51042e-08 6.51042e-08"/>
      <joint pos="0 0 0" axis="1 0 0" type="slide"/>
      <joint pos="0 0 0" axis="0 1 0" type="slide"/>
      <joint pos="0 0 0" axis="0 0 1" type="slide"/>
    </body>
    <body name="cloth_7" pos="-0.75 -0.05 0.1">
      <inertial pos="0 0 0" mass="0.00390625" diaginertia="6.51042e-08 6.51042e-08 6.51042e-08"/>
      <joint pos="0 0 0" axis="1 0 0" type="slide"/>
      <joint pos="0 0 0" axis="0 1 0" type="slide"/>
      <joint pos="0 0 0" axis="0 0 1" type="slide"/>
    </body>
    <body name="cloth_8" pos="-0.75 0.05 0.1">
      <inertial pos="0 0 0" mass="0.00390625" diaginertia="6.51042e-08 6.51042e-08 6.51042e-08"/>
      <joint pos="0 0 0" axis="1 0 0" type="slide"/>
      <joint pos="0 0 0" axis="0 1 0" type="slide"/>
      <joint pos="0 0 0" axis="0 0 1" type="slide"/>
    </body>
    <body name="cloth_9" pos="-0.75 0.15 0.1">
      <inertial pos="0 0 0" mass="0.00390625" diaginertia="6.51042e-08 6.51042e-08 6.51042e-08"/>
      <joint pos="0 0 0" axis="1 0 0" type="slide"/>
      <joint pos="0 0 0" axis="0 1 0" type="slide"/>
      <joint pos="0 0 0" axis="0 0 1" type="slide"/>
    </body>
    <body name="cloth_10" pos="-0.75 0.25 0.1">
      <inertial pos="0 0 0" mass="0.00390625" diaginertia="6.51042e-08 6.51042e-08 6.51042e-08"/>
      <joint pos="0 0 0" axis="1 0 0" type="slide"/>
      <joint pos="0 0 0" axis="0 1 0" type="slide"/>
      <joint pos="0 0 0" axis="0 0 1" type="slide"/>
    </body>
    <body name="cloth_11" pos="-0.75 0.35 0.1">
      <inertial pos="0 0 0" mass="0.00390625" diaginertia="6.51042e-08 6.51042e-08 6.51042e-08"/>
      <joint pos="0 0 0" axis="1 0 0" type="slide"/>
      <joint pos="0 0 0" axis="0 1 0" type="slide"/>
      <joint pos="0 0 0" axis="0 0 1" type="slide"/>
    </body>
    <body name="cloth_12" pos="-0.75 0.45 0.1">
      <inertial pos="0 0 0" mass="0.00390625" diaginertia="6.51042e-08 6.51042e-08 6.51042e-08"/>
      <joint pos="0 0 0" axis="1 0 0" type="slide"/>
      <joint pos="0 0 0" axis="0 1 0" type="slide"/>
      <joint pos="0 0 0" axis="0 0 1" type="slide"/>
    </body>
    <body name="cloth_13" pos="-0.75 0.55 0.1">
      <inertial pos="0 0 0" mass="0.00390625" diaginertia="6.51042e-08 6.51042e-08 6.51042e-08"/>
      <joint pos="0 0 0" axis="1 0 0" type="slide"/>
      <joint pos="0 0 0" axis="0 1 0" type="slide"/>
      <joint pos="0 0 0" axis="0 0 1" type="slide"/>
    </body>
    <body name="cloth_14" pos="-0.75 0.65 0.1">
      <inertial pos="0 0 0" mass="0.00390625" diaginertia="6.51042e-08 6.51042e-08 6.51042e-08"/>
      <joint pos="0 0 0" axis="1 0 0" type="slide"/>
      <joint pos="0 0 0" axis="0 1 0" type="slide"/>
      <joint pos="0 0 0" axis="0 0 1" type="slide"/>
    </body>
    <body name="cloth_15" pos="-0.75 0.75 0.1">
      <inertial pos="0 0 0" mass="0.00390625" diaginertia="6.51042e-08 6.51042e-08 6.51042e-08"/>
      <joint pos="0 0 0" axis="1 0 0" type="slide"/>
      <joint pos="0 0 0" axis="0 1 0" type="slide"/>
      <joint pos="0 0 0" axis="0 0 1" type="slide"/>
    </body>
    <body name="cloth_16" pos="-0.65 -0.75 0.1">
      <inertial pos="0 0 0" mass="0.00390625" diaginertia="6.51042e-08 6.51042e-08 6.51042e-08"/>
      <joint pos="0 0 0" axis="1 0 0" type="slide"/>
      <joint pos="0 0 0" axis="0 1 0" type="slide"/>
      <joint pos="0 0 0" axis="0 0 1" type="slide"/>
    </body>
    <body name="cloth_17" pos="-0.65 -0.65 0.1">
      <inertial pos="0 0 0" mass="0.00390625" diaginertia="6.51042e-08 6.51042e-08 6.51042e-08"/>
      <joint pos="0 0 0" axis="1 0 0" type="slide"/>
      <joint pos="0 0 0" axis="0 1 0" type="slide"/>
      <joint pos="0 0 0" axis="0 0 1" type="slide"/>
    </body>
    <body name="cloth_18" pos="-0.65 -0.55 0.1">
      <inertial pos="0 0 0" mass="0.00390625" diaginertia="6.51042e-08 6.51042e-08 6.51042e-08"/>
      <joint pos="0 0 0" axis="1 0 0" type="slide"/>
      <joint pos="0 0 0" axis="0 1 0" type="slide"/>
      <joint pos="0 0 0" axis="0 0 1" type="slide"/>
    </body>
    <body name="cloth_19" pos="-0.65 -0.45 0.1">
      <inertial pos="0 0 0" mass="0.00390625" diaginertia="6.51042e-08 6.51042e-08 6.51042e-08"/>
      <joint pos="0 0 0" axis="1 0 0" type="slide"/>
      <joint pos="0 0 0" axis="0 1 0" type="slide"/>
      <joint pos="0 0 0" axis="0 0 1" type="slide"/>
    </body>
    <body name="cloth_20" pos="-0.65 -0.35 0.1">
      <inertial pos="0 0 0" mass="0.00390625" diaginertia="6.51042e-08 6.51042e-08 6.51042e-08"/>
      <joint pos="0 0 0" axis="1 0 0" type="slide"/>
      <joint pos="0 0 0" axis="0 1 0" type="slide"/>
      <joint pos="0 0 0" axis="0 0 1" type="slide"/>
    </body>
    <body name="cloth_21" pos="-0.65 -0.25 0.1">
      <inertial pos="0 0 0" mass="0.00390625" diaginertia="6.51042e-08 6.51042e-08 6.51042e-08"/>
      <joint pos="0 0 0" axis="1 0 0" type="slide"/>
      <joint pos="0 0 0" axis="0 1 0" type="slide"/>
      <joint pos="0 0 0" axis="0 0 1" type="slide"/>
    </body>
    <body name="cloth_22" pos="-0.65 -0.15 0.1">
      <inertial pos="0 0 0" mass="0.00390625" diaginertia="6.51042e-08 6.51042e-08 6.51042e-08"/>
      <joint pos="0 0 0" axis="1 0 0" type="slide"/>
      <joint pos="0 0 0" axis="0 1 0" type="slide"/>
      <joint pos="0 0 0" axis="0 0 1" type="slide"/>
    </body>
    <body name="cloth_23" pos="-0.65 -0.05 0.1">
      <inertial pos="0 0 0" mass="0.00390625" diaginertia="6.51042e-08 6.51042e-08 6.51042e-08"/>
      <joint pos="0 0 0" axis="1 0 0" type="slide"/>
      <joint pos="0 0 0" axis="0 1 0" type="slide"/>
      <joint pos="0 0 0" axis="0 0 1" type="slide"/>
    </body>
    <body name="cloth_24" pos="-0.65 0.05 0.1">
      <inertial pos="0 0 0" mass="0.00390625" diaginertia="6.51042e-08 6.51042e-08 6.51042e-08"/>
      <joint pos="0 0 0" axis="1 0 0" type="slide"/>
      <joint pos="0 0 0" axis="0 1 0" type="slide"/>
      <joint pos="0 0 0" axis="0 0 1" type="slide"/>
    </body>
    <body name="cloth_25" pos="-0.65 0.15 0.1">
      <inertial pos="0 0 0" mass="0.00390625" diaginertia="6.51042e-08 6.51042e-08 6.51042e-08"/>
      <joint pos="0 0 0" axis="1 0 0" type="slide"/>
      <joint pos="0 0 0" axis="0 1 0" type="slide"/>
      <joint pos="0 0 0" axis="0 0 1" type="slide"/>
    </body>
    <body name="cloth_26" pos="-0.65 0.25 0.1">
      <inertial pos="0 0 0" mass="0.00390625" diaginertia="6.51042e-08 6.51042e-08 6.51042e-08"/>
      <joint pos="0 0 0" axis="1 0 0" type="slide"/>
      <joint pos="0 0 0" axis="0 1 0" type="slide"/>
      <joint pos="0 0 0" axis="0 0 1" type="slide"/>
    </body>
    <body name="cloth_27" pos="-0.65 0.35 0.1">
      <inertial pos="0 0 0" mass="0.00390625" diaginertia="6.51042e-08 6.51042e-08 6.51042e-08"/>
      <joint pos="0 0 0" axis="1 0 0" type="slide"/>
      <joint pos="0 0 0" axis="0 1 0" type="slide"/>
      <joint pos="0 0 0" axis="0 0 1" type="slide"/>
    </body>
    <body name="cloth_28" pos="-0.65 0.45 0.1">
      <inertial pos="0 0 0" mass="0.00390625" diaginertia="6.51042e-08 6.51042e-08 6.51042e-08"/>
      <joint pos="0 0 0" axis="1 0 0" type="slide"/>
      <joint pos="0 0 0" axis="0 1 0" type="slide"/>
      <joint pos="0 0 0" axis="0 0 1" type="slide"/>
    </body>
    <body name="cloth_29" pos="-0.65 0.55 0.1">
      <inertial pos="0 0 0" mass="0.00390625" diaginertia="6.51042e-08 6.51042e-08 6.51042e-08"/>
      <joint pos="0 0 0" axis="1 0 0" type="slide"/>
      <joint pos="0 0 0" axis="0 1 0" type="slide"/>
      <joint pos="0 0 0" axis="0 0 1" type="slide"/>
    </body>
    <body name="cloth_30" pos="-0.65 0.65 0.1">
      <inertial pos="0 0 0" mass="0.00390625" diaginertia="6.51042e-08 6.51042e-08 6.51042e-08"/>
      <joint pos="0 0 0" axis="1 0 0" type="slide"/>
      <joint pos="0 0 0" axis="0 1 0" type="slide"/>
      <joint pos="0 0 0" axis="0 0 1" type="slide"/>
    </body>
    <body name="cloth_31" pos="-0.65 0.75 0.1">
      <inertial pos="0 0 0" mass="0.00390625" diaginertia="6.51042e-08 6.51042e-08 6.51042e-08"/>
      <joint pos="0 0 0" axis="1 0 0" type="slide"/>
      <joint pos="0 0 0" axis="0 1 0" type="slide"/>
      <joint pos="0 0 0" axis="0 0 1" type="slide"/>
    </body>
    <body name="cloth_32" pos="-0.55 -0.75 0.1">
      <inertial pos="0 0 0" mass="0.00390625" diaginertia="6.51042e-08 6.51042e-08 6.51042e-08"/>
      <joint pos="0 0 0" axis="1 0 0" type="slide"/>
      <joint pos="0 0 0" axis="0 1 0" type="slide"/>
      <joint pos="0 0 0" axis="0 0 1" type="slide"/>
    </body>
    <body name="cloth_33" pos="-0.55 -0.65 0.1">
      <inertial pos="0 0 0" mass="0.00390625" diaginertia="6.51042e-08 6.51042e-08 6.51042e-08"/>
      <joint pos="0 0 0" axis="1 0 0" type="slide"/>
      <joint pos="0 0 0" axis="0 1 0" type="slide"/>
      <joint pos="0 0 0" axis="0 0 1" type="slide"/>
    </body>
    <body name="cloth_34" pos="-0.55 -0.55 0.1">
      <inertial pos="0 0 0" mass="0.00390625" diaginertia="6.51042e-08 6.51042e-08 6.51042e-08"/>
      <joint pos="0 0 0" axis="1 0 0" type="slide"/>
      <joint pos="0 0 0" axis="0 1 0" type="slide"/>
      <joint pos="0 0 0" axis="0 0 1" type="slide"/>
    </body>
    <body name="cloth_35" pos="-0.55 -0.45 0.1">
      <inertial pos="0 0 0" mass="0.00390625" diaginertia="6.51042e-08 6.51042e-08 6.51042e-08"/>
      <joint pos="0 0 0" axis="1 0 0" type="slide"/>
      <joint pos="0 0 0" axis="0 1 0" type="slide"/>
      <joint pos="0 0 0" axis="0 0 1" type="slide"/>
    </body>
    <body name="cloth_36" pos="-0.55 -0.35 0.1">
      <inertial pos="0 0 0" mass="0.00390625" diaginertia="6.51042e-08 6.51042e-08 6.51042e-08"/>
      <joint pos="0 0 0" axis="1 0 0" type="slide"/>
      <joint pos="0 0 0" axis="0 1 0" type="slide"/>
      <joint pos="0 0 0" axis="0 0 1" type="slide"/>
    </body>
    <body name="cloth_37" pos="-0.55 -0.25 0.1">
      <inertial pos="0 0 0" mass="0.00390625" diaginertia="6.51042e-08 6.51042e-08 6.51042e-08"/>
      <joint pos="0 0 0" axis="1 0 0" type="slide"/>
      <joint pos="0 0 0" axis="0 1 0" type="slide"/>
      <joint pos="0 0 0" axis="0 0 1" type="slide"/>
    </body>
    <body name="cloth_38" pos="-0.55 -0.15 0.1">
      <inertial pos="0 0 0" mass="0.00390625" diaginertia="6.51042e-08 6.51042e-08 6.51042e-08"/>
      <joint pos="0 0 0" axis="1 0 0" type="slide"/>
      <joint pos="0 0 0" axis="0 1 0" type="slide"/>
      <joint pos="0 0 0" axis="0 0 1" type="slide"/>
    </body>
    <body name="cloth_39" pos="-0.55 -0.05 0.1">
      <inertial pos="0 0 0" mass="0.00390625" diaginertia="6.51042e-08 6.51042e-08 6.51042e-08"/>
      <joint pos="0 0 0" axis="1 0 0" type="slide"/>
      <joint pos="0 0 0" axis="0 1 0" type="slide"/>
      <joint pos="0 0 0" axis="0 0 1" type="slide"/>
    </body>
    <body name="cloth_40" pos="-0.55 0.05 0.1">
      <inertial pos="0 0 0" mass="0.00390625" diaginertia="6.51042e-08 6.51042e-08 6.51042e-08"/>
      <joint pos="0 0 0" axis="1 0 0" type="slide"/>
      <joint pos="0 0 0" axis="0 1 0" type="slide"/>
      <joint pos="0 0 0" axis="0 0 1" type="slide"/>
    </body>
    <body name="cloth_41" pos="-0.55 0.15 0.1">
      <inertial pos="0 0 0" mass="0.00390625" diaginertia="6.51042e-08 6.51042e-08 6.51042e-08"/>
      <joint pos="0 0 0" axis="1 0 0" type="slide"/>
      <joint pos="0 0 0" axis="0 1 0" type="slide"/>
      <joint pos="0 0 0" axis="0 0 1" type="slide"/>
    </body>
    <body name="cloth_42" pos="-0.55 0.25 0.1">
      <inertial pos="0 0 0" mass="0.00390625" diaginertia="6.51042e-08 6.51042e-08 6.51042e-08"/>
      <joint pos="0 0 0" axis="1 0 0" type="slide"/>
      <joint pos="0 0 0" axis="0 1 0" type="slide"/>
      <joint pos="0 0 0" axis="0 0 1" type="slide"/>
    </body>
    <body name="cloth_43" pos="-0.55 0.35 0.1">
      <inertial pos="0 0 0" mass="0.00390625" diaginertia="6.51042e-08 6.51042e-08 6.51042e-08"/>
      <joint pos="0 0 0" axis="1 0 0" type="slide"/>
      <joint pos="0 0 0" axis="0 1 0" type="slide"/>
      <joint pos="0 0 0" axis="0 0 1" type="slide"/>
    </body>
    <body name="cloth_44" pos="-0.55 0.45 0.1">
      <inertial pos="0 0 0" mass="0.00390625" diaginertia="6.51042e-08 6.51042e-08 6.51042e-08"/>
      <joint pos="0 0 0" axis="1 0 0" type="slide"/>
      <joint pos="0 0 0" axis="0 1 0" type="slide"/>
      <joint pos="0 0 0" axis="0 0 1" type="slide"/>
    </body>
    <body name="cloth_45" pos="-0.55 0.55 0.1">
      <inertial pos="0 0 0" mass="0.00390625" diaginertia="6.51042e-08 6.51042e-08 6.51042e-08"/>
      <joint pos="0 0 0" axis="1 0 0" type="slide"/>
      <joint pos="0 0 0" axis="0 1 0" type="slide"/>
      <joint pos="0 0 0" axis="0 0 1" type="slide"/>
    </body>
    <body name="cloth_46" pos="-0.55 0.65 0.1">
      <inertial pos="0 0 0" mass="0.00390625" diaginertia="6.51042e-08 6.51042e-08 6.51042e-08"/>
      <joint pos="0 0 0" axis="1 0 0" type="slide"/>
      <joint pos="0 0 0" axis="0 1 0" type="slide"/>
      <joint pos="0 0 0" axis="0 0 1" type="slide"/>
    </body>
    <body name="cloth_47" pos="-0.55 0.75 0.1">
      <inertial pos="0 0 0" mass="0.00390625" diaginertia="6.51042e-08 6.51042e-08 6.51042e-08"/>
      <joint pos="0 0 0" axis="1 0 0" type="slide"/>
      <joint pos="0 0 0" axis="0 1 0" type="slide"/>
      <joint pos="0 0 0" axis="0 0 1" type="slide"/>
    </body>
    <body name="cloth_48" pos="-0.45 -0.75 0.1">
      <inertial pos="0 0 0" mass="0.00390625" diaginertia="6.51042e-08 6.51042e-08 6.51042e-08"/>
      <joint pos="0 0 0" axis="1 0 0" type="slide"/>
      <joint pos="0 0 0" axis="0 1 0" type="slide"/>
      <joint pos="0 0 0" axis="0 0 1" type="slide"/>
    </body>
    <body name="cloth_49" pos="-0.45 -0.65 0.1">
      <inertial pos="0 0 0" mass="0.00390625" diaginertia="6.51042e-08 6.51042e-08 6.51042e-08"/>
      <joint pos="0 0 0" axis="1 0 0" type="slide"/>
      <joint pos="0 0 0" axis="0 1 0" type="slide"/>
      <joint pos="0 0 0" axis="0 0 1" type="slide"/>
    </body>
    <body name="cloth_50" pos="-0.45 -0.55 0.1">
      <inertial pos="0 0 0" mass="0.00390625" diaginertia="6.51042e-08 6.51042e-08 6.51042e-08"/>
      <joint pos="0 0 0" axis="1 0 0" type="slide"/>
      <joint pos="0 0 0" axis="0 1 0" type="slide"/>
      <joint pos="0 0 0" axis="0 0 1" type="slide"/>
    </body>
    <body name="cloth_51" pos="-0.45 -0.45 0.1">
      <inertial pos="0 0 0" mass="0.00390625" diaginertia="6.51042e-08 6.51042e-08 6.51042e-08"/>
      <joint pos="0 0 0" axis="1 0 0" type="slide"/>
      <joint pos="0 0 0" axis="0 1 0" type="slide"/>
      <joint pos="0 0 0" axis="0 0 1" type="slide"/>
    </body>
    <body name="cloth_52" pos="-0.45 -0.35 0.1">
      <inertial pos="0 0 0" mass="0.00390625" diaginertia="6.51042e-08 6.51042e-08 6.51042e-08"/>
      <joint pos="0 0 0" axis="1 0 0" type="slide"/>
      <joint pos="0 0 0" axis="0 1 0" type="slide"/>
      <joint pos="0 0 0" axis="0 0 1" type="slide"/>
    </body>
    <body name="cloth_53" pos="-0.45 -0.25 0.1">
      <inertial pos="0 0 0" mass="0.00390625" diaginertia="6.51042e-08 6.51042e-08 6.51042e-08"/>
      <joint pos="0 0 0" axis="1 0 0" type="slide"/>
      <joint pos="0 0 0" axis="0 1 0" type="slide"/>
      <joint pos="0 0 0" axis="0 0 1" type="slide"/>
    </body>
    <body name="cloth_54" pos="-0.45 -0.15 0.1">
      <inertial pos="0 0 0" mass="0.00390625" diaginertia="6.51042e-08 6.51042e-08 6.51042e-08"/>
      <joint pos="0 0 0" axis="1 0 0" type="slide"/>
      <joint pos="0 0 0" axis="0 1 0" type="slide"/>
      <joint pos="0 0 0" axis="0 0 1" type="slide"/>
    </body>
    <body name="cloth_55" pos="-0.45 -0.05 0.1">
      <inertial pos="0 0 0" mass="0.00390625" diaginertia="6.51042e-08 6.51042e-08 6.51042e-08"/>
      <joint pos="0 0 0" axis="1 0 0" type="slide"/>
      <joint pos="0 0 0" axis="0 1 0" type="slide"/>
      <joint pos="0 0 0" axis="0 0 1" type="slide"/>
    </body>
    <body name="cloth_56" pos="-0.45 0.05 0.1">
      <inertial pos="0 0 0" mass="0.00390625" diaginertia="6.51042e-08 6.51042e-08 6.51042e-08"/>
      <joint pos="0 0 0" axis="1 0 0" type="slide"/>
      <joint pos="0 0 0" axis="0 1 0" type="slide"/>
      <joint pos="0 0 0" axis="0 0 1" type="slide"/>
    </body>
    <body name="cloth_57" pos="-0.45 0.15 0.1">
      <inertial pos="0 0 0" mass="0.00390625" diaginertia="6.51042e-08 6.51042e-08 6.51042e-08"/>
      <joint pos="0 0 0" axis="1 0 0" type="slide"/>
      <joint pos="0 0 0" axis="0 1 0" type="slide"/>
      <joint pos="0 0 0" axis="0 0 1" type="slide"/>
    </body>
    <body name="cloth_58" pos="-0.45 0.25 0.1">
      <inertial pos="0 0 0" mass="0.00390625" diaginertia="6.51042e-08 6.51042e-08 6.51042e-08"/>
      <joint pos="0 0 0" axis="1 0 0" type="slide"/>
      <joint pos="0 0 0" axis="0 1 0" type="slide"/>
      <joint pos="0 0 0" axis="0 0 1" type="slide"/>
    </body>
    <body name="cloth_59" pos="-0.45 0.35 0.1">
      <inertial pos="0 0 0" mass="0.00390625" diaginertia="6.51042e-08 6.51042e-08 6.51042e-08"/>
      <joint pos="0 0 0" axis="1 0 0" type="slide"/>
      <joint pos="0 0 0" axis="0 1 0" type="slide"/>
      <joint pos="0 0 0" axis="0 0 1" type="slide"/>
    </body>
    <body name="cloth_60" pos="-0.45 0.45 0.1">
      <inertial pos="0 0 0" mass="0.00390625" diaginertia="6.51042e-08 6.51042e-08 6.51042e-08"/>
      <joint pos="0 0 0" axis="1 0 0" type="slide"/>
      <joint pos="0 0 0" axis="0 1 0" type="slide"/>
      <joint pos="0 0 0" axis="0 0 1" type="slide"/>
    </body>
    <body name="cloth_61" pos="-0.45 0.55 0.1">
      <inertial pos="0 0 0" mass="0.00390625" diaginertia="6.51042e-08 6.51042e-08 6.51042e-08"/>
      <joint pos="0 0 0" axis="1 0 0" type="slide"/>
      <joint pos="0 0 0" axis="0 1 0" type="slide"/>
      <joint pos="0 0 0" axis="0 0 1" type="slide"/>
    </body>
    <body name="cloth_62" pos="-0.45 0.65 0.1">
      <inertial pos="0 0 0" mass="0.00390625" diaginertia="6.51042e-08 6.51042e-08 6.51042e-08"/>
      <joint pos="0 0 0" axis="1 0 0" type="slide"/>
      <joint pos="0 0 0" axis="0 1 0" type="slide"/>
      <joint pos="0 0 0" axis="0 0 1" type="slide"/>
    </body>
    <body name="cloth_63" pos="-0.45 0.75 0.1">
      <inertial pos="0 0 0" mass="0.00390625" diaginertia="6.51042e-08 6.51042e-08 6.51042e-08"/>
      <joint pos="0 0 0" axis="1 0 0" type="slide"/>
      <joint pos="0 0 0" axis="0 1 0" type="slide"/>
      <joint pos="0 0 0" axis="0 0 1" type="slide"/>
    </body>
    <body name="cloth_64" pos="-0.35 -0.75 0.1">
      <inertial pos="0 0 0" mass="0.00390625" diaginertia="6.51042e-08 6.51042e-08 6.51042e-08"/>
      <joint pos="0 0 0" axis="1 0 0" type="slide"/>
      <joint pos="0 0 0" axis="0 1 0" type="slide"/>
      <joint pos="0 0 0" axis="0 0 1" type="slide"/>
    </body>
    <body name="cloth_65" pos="-0.35 -0.65 0.1">
      <inertial pos="0 0 0" mass="0.00390625" diaginertia="6.51042e-08 6.51042e-08 6.51042e-08"/>
      <joint pos="0 0 0" axis="1 0 0" type="slide"/>
      <joint pos="0 0 0" axis="0 1 0" type="slide"/>
      <joint pos="0 0 0" axis="0 0 1" type="slide"/>
    </body>
    <body name="cloth_66" pos="-0.35 -0.55 0.1">
      <inertial pos="0 0 0" mass="0.00390625" diaginertia="6.51042e-08 6.51042e-08 6.51042e-08"/>
      <joint pos="0 0 0" axis="1 0 0" type="slide"/>
      <joint pos="0 0 0" axis="0 1 0" type="slide"/>
      <joint pos="0 0 0" axis="0 0 1" type="slide"/>
    </body>
    <body name="cloth_67" pos="-0.35 -0.45 0.1">
      <inertial pos="0 0 0" mass="0.00390625" diaginertia="6.51042e-08 6.51042e-08 6.51042e-08"/>
      <joint pos="0 0 0" axis="1 0 0" type="slide"/>
      <joint pos="0 0 0" axis="0 1 0" type="slide"/>
      <joint pos="0 0 0" axis="0 0 1" type="slide"/>
    </body>
    <body name="cloth_68" pos="-0.35 -0.35 0.1">
      <inertial pos="0 0 0" mass="0.00390625" diaginertia="6.51042e-08 6.51042e-08 6.51042e-08"/>
      <joint pos="0 0 0" axis="1 0 0" type="slide"/>
      <joint pos="0 0 0" axis="0 1 0" type="slide"/>
      <joint pos="0 0 0" axis="0 0 1" type="slide"/>
    </body>
    <body name="cloth_69" pos="-0.35 -0.25 0.1">
      <inertial pos="0 0 0" mass="0.00390625" diaginertia="6.51042e-08 6.51042e-08 6.51042e-08"/>
      <joint pos="0 0 0" axis="1 0 0" type="slide"/>
      <joint pos="0 0 0" axis="0 1 0" type="slide"/>
      <joint pos="0 0 0" axis="0 0 1" type="slide"/>
    </body>
    <body name="cloth_70" pos="-0.35 -0.15 0.1">
      <inertial pos="0 0 0" mass="0.00390625" diaginertia="6.51042e-08 6.51042e-08 6.51042e-08"/>
      <joint pos="0 0 0" axis="1 0 0" type="slide"/>
      <joint pos="0 0 0" axis="0 1 0" type="slide"/>
      <joint pos="0 0 0" axis="0 0 1" type="slide"/>
    </body>
    <body name="cloth_71" pos="-0.35 -0.05 0.1">
      <inertial pos="0 0 0" mass="0.00390625" diaginertia="6.51042e-08 6.51042e-08 6.51042e-08"/>
      <joint pos="0 0 0" axis="1 0 0" type="slide"/>
      <joint pos="0 0 0" axis="0 1 0" type="slide"/>
      <joint pos="0 0 0" axis="0 0 1" type="slide"/>
    </body>
    <body name="cloth_72" pos="-0.35 0.05 0.1">
      <inertial pos="0 0 0" mass="0.00390625" diaginertia="6.51042e-08 6.51042e-08 6.51042e-08"/>
      <joint pos="0 0 0" axis="1 0 0" type="slide"/>
      <joint pos="0 0 0" axis="0 1 0" type="slide"/>
      <joint pos="0 0 0" axis="0 0 1" type="slide"/>
    </body>
    <body name="cloth_73" pos="-0.35 0.15 0.1">
      <inertial pos="0 0 0" mass="0.00390625" diaginertia="6.51042e-08 6.51042e-08 6.51042e-08"/>
      <joint pos="0 0 0" axis="1 0 0" type="slide"/>
      <joint pos="0 0 0" axis="0 1 0" type="slide"/>
      <joint pos="0 0 0" axis="0 0 1" type="slide"/>
    </body>
    <body name="cloth_74" pos="-0.35 0.25 0.1">
      <inertial pos="0 0 0" mass="0.00390625" diaginertia="6.51042e-08 6.51042e-08 6.51042e-08"/>
      <joint pos="0 0 0" axis="1 0 0" type="slide"/>
      <joint pos="0 0 0" axis="0 1 0" type="slide"/>
      <joint pos="0 0 0" axis="0 0 1" type="slide"/>
    </body>
    <body name="cloth_75" pos="-0.35 0.35 0.1">
      <inertial pos="0 0 0" mass="0.00390625" diaginertia="6.51042e-08 6.51042e-08 6.51042e-08"/>
      <joint pos="0 0 0" axis="1 0 0" type="slide"/>
      <joint pos="0 0 0" axis="0 1 0" type="slide"/>
      <joint pos="0 0 0" axis="0 0 1" type="slide"/>
    </body>
    <body name="cloth_76" pos="-0.35 0.45 0.1">
      <inertial pos="0 0 0" mass="0.00390625" diaginertia="6.51042e-08 6.51042e-08 6.51042e-08"/>
      <joint pos="0 0 0" axis="1 0 0" type="slide"/>
      <joint pos="0 0 0" axis="0 1 0" type="slide"/>
      <joint pos="0 0 0" axis="0 0 1" type="slide"/>
    </body>
    <body name="cloth_77" pos="-0.35 0.55 0.1">
      <inertial pos="0 0 0" mass="0.00390625" diaginertia="6.51042e-08 6.51042e-08 6.51042e-08"/>
      <joint pos="0 0 0" axis="1 0 0" type="slide"/>
      <joint pos="0 0 0" axis="0 1 0" type="slide"/>
      <joint pos="0 0 0" axis="0 0 1" type="slide"/>
    </body>
    <body name="cloth_78" pos="-0.35 0.65 0.1">
      <inertial pos="0 0 0" mass="0.00390625" diaginertia="6.51042e-08 6.51042e-08 6.51042e-08"/>
      <joint pos="0 0 0" axis="1 0 0" type="slide"/>
      <joint pos="0 0 0" axis="0 1 0" type="slide"/>
      <joint pos="0 0 0" axis="0 0 1" type="slide"/>
    </body>
    <body name="cloth_79" pos="-0.35 0.75 0.1">
      <inertial pos="0 0 0" mass="0.00390625" diaginertia="6.51042e-08 6.51042e-08 6.51042e-08"/>
      <joint pos="0 0 0" axis="1 0 0" type="slide"/>
      <joint pos="0 0 0" axis="0 1 0" type="slide"/>
      <joint pos="0 0 0" axis="0 0 1" type="slide"/>
    </body>
    <body name="cloth_80" pos="-0.25 -0.75 0.1">
      <inertial pos="0 0 0" mass="0.00390625" diaginertia="6.51042e-08 6.51042e-08 6.51042e-08"/>
      <joint pos="0 0 0" axis="1 0 0" type="slide"/>
      <joint pos="0 0 0" axis="0 1 0" type="slide"/>
      <joint pos="0 0 0" axis="0 0 1" type="slide"/>
    </body>
    <body name="cloth_81" pos="-0.25 -0.65 0.1">
      <inertial pos="0 0 0" mass="0.00390625" diaginertia="6.51042e-08 6.51042e-08 6.51042e-08"/>
      <joint pos="0 0 0" axis="1 0 0" type="slide"/>
      <joint pos="0 0 0" axis="0 1 0" type="slide"/>
      <joint pos="0 0 0" axis="0 0 1" type="slide"/>
    </body>
    <body name="cloth_82" pos="-0.25 -0.55 0.1">
      <inertial pos="0 0 0" mass="0.00390625" diaginertia="6.51042e-08 6.51042e-08 6.51042e-08"/>
      <joint pos="0 0 0" axis="1 0 0" type="slide"/>
      <joint pos="0 0 0" axis="0 1 0" type="slide"/>
      <joint pos="0 0 0" axis="0 0 1" type="slide"/>
    </body>
    <body name="cloth_83" pos="-0.25 -0.45 0.1">
      <inertial pos="0 0 0" mass="0.00390625" diaginertia="6.51042e-08 6.51042e-08 6.51042e-08"/>
      <joint pos="0 0 0" axis="1 0 0" type="slide"/>
      <joint pos="0 0 0" axis="0 1 0" type="slide"/>
      <joint pos="0 0 0" axis="0 0 1" type="slide"/>
    </body>
    <body name="cloth_84" pos="-0.25 -0.35 0.1">
      <inertial pos="0 0 0" mass="0.00390625" diaginertia="6.51042e-08 6.51042e-08 6.51042e-08"/>
      <joint pos="0 0 0" axis="1 0 0" type="slide"/>
      <joint pos="0 0 0" axis="0 1 0" type="slide"/>
      <joint pos="0 0 0" axis="0 0 1" type="slide"/>
    </body>
    <body name="cloth_85" pos="-0.25 -0.25 0.1">
      <inertial pos="0 0 0" mass="0.00390625" diaginertia="6.51042e-08 6.51042e-08 6.51042e-08"/>
      <joint pos="0 0 0" axis="1 0 0" type="slide"/>
      <joint pos="0 0 0" axis="0 1 0" type="slide"/>
      <joint pos="0 0 0" axis="0 0 1" type="slide"/>
    </body>
    <body name="cloth_86" pos="-0.25 -0.15 0.1">
      <inertial pos="0 0 0" mass="0.00390625" diaginertia="6.51042e-08 6.51042e-08 6.51042e-08"/>
      <joint pos="0 0 0" axis="1 0 0" type="slide"/>
      <joint pos="0 0 0" axis="0 1 0" type="slide"/>
      <joint pos="0 0 0" axis="0 0 1" type="slide"/>
    </body>
    <body name="cloth_87" pos="-0.25 -0.05 0.1">
      <inertial pos="0 0 0" mass="0.00390625" diaginertia="6.51042e-08 6.51042e-08 6.51042e-08"/>
      <joint pos="0 0 0" axis="1 0 0" type="slide"/>
      <joint pos="0 0 0" axis="0 1 0" type="slide"/>
      <joint pos="0 0 0" axis="0 0 1" type="slide"/>
    </body>
    <body name="cloth_88" pos="-0.25 0.05 0.1">
      <inertial pos="0 0 0" mass="0.00390625" diaginertia="6.51042e-08 6.51042e-08 6.51042e-08"/>
      <joint pos="0 0 0" axis="1 0 0" type="slide"/>
      <joint pos="0 0 0" axis="0 1 0" type="slide"/>
      <joint pos="0 0 0" axis="0 0 1" type="slide"/>
    </body>
    <body name="cloth_89" pos="-0.25 0.15 0.1">
      <inertial pos="0 0 0" mass="0.00390625" diaginertia="6.51042e-08 6.51042e-08 6.51042e-08"/>
      <joint pos="0 0 0" axis="1 0 0" type="slide"/>
      <joint pos="0 0 0" axis="0 1 0" type="slide"/>
      <joint pos="0 0 0" axis="0 0 1" type="slide"/>
    </body>
    <body name="cloth_90" pos="-0.25 0.25 0.1">
      <inertial pos="0 0 0" mass="0.00390625" diaginertia="6.51042e-08 6.51042e-08 6.51042e-08"/>
      <joint pos="0 0 0" axis="1 0 0" type="slide"/>
      <joint pos="0 0 0" axis="0 1 0" type="slide"/>
      <joint pos="0 0 0" axis="0 0 1" type="slide"/>
    </body>
    <body name="cloth_91" pos="-0.25 0.35 0.1">
      <inertial pos="0 0 0" mass="0.00390625" diaginertia="6.51042e-08 6.51042e-08 6.51042e-08"/>
      <joint pos="0 0 0" axis="1 0 0" type="slide"/>
      <joint pos="0 0 0" axis="0 1 0" type="slide"/>
      <joint pos="0 0 0" axis="0 0 1" type="slide"/>
    </body>
    <body name="cloth_92" pos="-0.25 0.45 0.1">
      <inertial pos="0 0 0" mass="0.00390625" diaginertia="6.51042e-08 6.51042e-08 6.51042e-08"/>
      <joint pos="0 0 0" axis="1 0 0" type="slide"/>
      <joint pos="0 0 0" axis="0 1 0" type="slide"/>
      <joint pos="0 0 0" axis="0 0 1" type="slide"/>
    </body>
    <body name="cloth_93" pos="-0.25 0.55 0.1">
      <inertial pos="0 0 0" mass="0.00390625" diaginertia="6.51042e-08 6.51042e-08 6.51042e-08"/>
      <joint pos="0 0 0" axis="1 0 0" type="slide"/>
      <joint pos="0 0 0" axis="0 1 0" type="slide"/>
      <joint pos="0 0 0" axis="0 0 1" type="slide"/>
    </body>
    <body name="cloth_94" pos="-0.25 0.65 0.1">
      <inertial pos="0 0 0" mass="0.00390625" diaginertia="6.51042e-08 6.51042e-08 6.51042e-08"/>
      <joint pos="0 0 0" axis="1 0 0" type="slide"/>
      <joint pos="0 0 0" axis="0 1 0" type="slide"/>
      <joint pos="0 0 0" axis="0 0 1" type="slide"/>
    </body>
    <body name="cloth_95" pos="-0.25 0.75 0.1">
      <inertial pos="0 0 0" mass="0.00390625" diaginertia="6.51042e-08 6.51042e-08 6.51042e-08"/>
      <joint pos="0 0 0" axis="1 0 0" type="slide"/>
      <joint pos="0 0 0" axis="0 1 0" type="slide"/>
      <joint pos="0 0 0" axis="0 0 1" type="slide"/>
    </body>
    <body name="cloth_96" pos="-0.15 -0.75 0.1">
      <inertial pos="0 0 0" mass="0.00390625" diaginertia="6.51042e-08 6.51042e-08 6.51042e-08"/>
      <joint pos="0 0 0" axis="1 0 0" type="slide"/>
      <joint pos="0 0 0" axis="0 1 0" type="slide"/>
      <joint pos="0 0 0" axis="0 0 1" type="slide"/>
    </body>
    <body name="cloth_97" pos="-0.15 -0.65 0.1">
      <inertial pos="0 0 0" mass="0.00390625" diaginertia="6.51042e-08 6.51042e-08 6.51042e-08"/>
      <joint pos="0 0 0" axis="1 0 0" type="slide"/>
      <joint pos="0 0 0" axis="0 1 0" type="slide"/>
      <joint pos="0 0 0" axis="0 0 1" type="slide"/>
    </body>
    <body name="cloth_98" pos="-0.15 -0.55 0.1">
      <inertial pos="0 0 0" mass="0.00390625" diaginertia="6.51042e-08 6.51042e-08 6.51042e-08"/>
      <joint pos="0 0 0" axis="1 0 0" type="slide"/>
      <joint pos="0 0 0" axis="0 1 0" type="slide"/>
      <joint pos="0 0 0" axis="0 0 1" type="slide"/>
    </body>
    <body name="cloth_99" pos="-0.15 -0.45 0.1">
      <inertial pos="0 0 0" mass="0.00390625" diaginertia="6.51042e-08 6.51042e-08 6.51042e-08"/>
      <joint pos="0 0 0" axis="1 0 0" type="slide"/>
      <joint pos="0 0 0" axis="0 1 0" type="slide"/>
      <joint pos="0 0 0" axis="0 0 1" type="slide"/>
    </body>
    <body name="cloth_100" pos="-0.15 -0.35 0.1">
      <inertial pos="0 0 0" mass="0.00390625" diaginertia="6.51042e-08 6.51042e-08 6.51042e-08"/>
      <joint pos="0 0 0" axis="1 0 0" type="slide"/>
      <joint pos="0 0 0" axis="0 1 0" type="slide"/>
      <joint pos="0 0 0" axis="0 0 1" type="slide"/>
    </body>
    <body name="cloth_101" pos="-0.15 -0.25 0.1">
      <inertial pos="0 0 0" mass="0.00390625" diaginertia="6.51042e-08 6.51042e-08 6.51042e-08"/>
      <joint pos="0 0 0" axis="1 0 0" type="slide"/>
      <joint pos="0 0 0" axis="0 1 0" type="slide"/>
      <joint pos="0 0 0" axis="0 0 1" type="slide"/>
    </body>
    <body name="cloth_102" pos="-0.15 -0.15 0.1">
      <inertial pos="0 0 0" mass="0.00390625" diaginertia="6.51042e-08 6.51042e-08 6.51042e-08"/>
      <joint pos="0 0 0" axis="1 0 0" type="slide"/>
      <joint pos="0 0 0" axis="0 1 0" type="slide"/>
      <joint pos="0 0 0" axis="0 0 1" type="slide"/>
    </body>
    <body name="cloth_103" pos="-0.15 -0.05 0.1">
      <inertial pos="0 0 0" mass="0.00390625" diaginertia="6.51042e-08 6.51042e-08 6.51042e-08"/>
      <joint pos="0 0 0" axis="1 0 0" type="slide"/>
      <joint pos="0 0 0" axis="0 1 0" type="slide"/>
      <joint pos="0 0 0" axis="0 0 1" type="slide"/>
    </body>
    <body name="cloth_104" pos="-0.15 0.05 0.1">
      <inertial pos="0 0 0" mass="0.00390625" diaginertia="6.51042e-08 6.51042e-08 6.51042e-08"/>
      <joint pos="0 0 0" axis="1 0 0" type="slide"/>
      <joint pos="0 0 0" axis="0 1 0" type="slide"/>
      <joint pos="0 0 0" axis="0 0 1" type="slide"/>
    </body>
    <body name="cloth_105" pos="-0.15 0.15 0.1">
      <inertial pos="0 0 0" mass="0.00390625" diaginertia="6.51042e-08 6.51042e-08 6.51042e-08"/>
      <joint pos="0 0 0" axis="1 0 0" type="slide"/>
      <joint pos="0 0 0" axis="0 1 0" type="slide"/>
      <joint pos="0 0 0" axis="0 0 1" type="slide"/>
    </body>
    <body name="cloth_106" pos="-0.15 0.25 0.1">
      <inertial pos="0 0 0" mass="0.00390625" diaginertia="6.51042e-08 6.51042e-08 6.51042e-08"/>
      <joint pos="0 0 0" axis="1 0 0" type="slide"/>
      <joint pos="0 0 0" axis="0 1 0" type="slide"/>
      <joint pos="0 0 0" axis="0 0 1" type="slide"/>
    </body>
    <body name="cloth_107" pos="-0.15 0.35 0.1">
      <inertial pos="0 0 0" mass="0.00390625" diaginertia="6.51042e-08 6.51042e-08 6.51042e-08"/>
      <joint pos="0 0 0" axis="1 0 0" type="slide"/>
      <joint pos="0 0 0" axis="0 1 0" type="slide"/>
      <joint pos="0 0 0" axis="0 0 1" type="slide"/>
    </body>
    <body name="cloth_108" pos="-0.15 0.45 0.1">
      <inertial pos="0 0 0" mass="0.00390625" diaginertia="6.51042e-08 6.51042e-08 6.51042e-08"/>
      <joint pos="0 0 0" axis="1 0 0" type="slide"/>
      <joint pos="0 0 0" axis="0 1 0" type="slide"/>
      <joint pos="0 0 0" axis="0 0 1" type="slide"/>
    </body>
    <body name="cloth_109" pos="-0.15 0.55 0.1">
      <inertial pos="0 0 0" mass="0.00390625" diaginertia="6.51042e-08 6.51042e-08 6.51042e-08"/>
      <joint pos="0 0 0" axis="1 0 0" type="slide"/>
      <joint pos="0 0 0" axis="0 1 0" type="slide"/>
      <joint pos="0 0 0" axis="0 0 1" type="slide"/>
    </body>
    <body name="cloth_110" pos="-0.15 0.65 0.1">
      <inertial pos="0 0 0" mass="0.00390625" diaginertia="6.51042e-08 6.51042e-08 6.51042e-08"/>
      <joint pos="0 0 0" axis="1 0 0" type="slide"/>
      <joint pos="0 0 0" axis="0 1 0" type="slide"/>
      <joint pos="0 0 0" axis="0 0 1" type="slide"/>
    </body>
    <body name="cloth_111" pos="-0.15 0.75 0.1">
      <inertial pos="0 0 0" mass="0.00390625" diaginertia="6.51042e-08 6.51042e-08 6.51042e-08"/>
      <joint pos="0 0 0" axis="1 0 0" type="slide"/>
      <joint pos="0 0 0" axis="0 1 0" type="slide"/>
      <joint pos="0 0 0" axis="0 0 1" type="slide"/>
    </body>
    <body name="cloth_112" pos="-0.05 -0.75 0.1">
      <inertial pos="0 0 0" mass="0.00390625" diaginertia="6.51042e-08 6.51042e-08 6.51042e-08"/>
      <joint pos="0 0 0" axis="1 0 0" type="slide"/>
      <joint pos="0 0 0" axis="0 1 0" type="slide"/>
      <joint pos="0 0 0" axis="0 0 1" type="slide"/>
    </body>
    <body name="cloth_113" pos="-0.05 -0.65 0.1">
      <inertial pos="0 0 0" mass="0.00390625" diaginertia="6.51042e-08 6.51042e-08 6.51042e-08"/>
      <joint pos="0 0 0" axis="1 0 0" type="slide"/>
      <joint pos="0 0 0" axis="0 1 0" type="slide"/>
      <joint pos="0 0 0" axis="0 0 1" type="slide"/>
    </body>
    <body name="cloth_114" pos="-0.05 -0.55 0.1">
      <inertial pos="0 0 0" mass="0.00390625" diaginertia="6.51042e-08 6.51042e-08 6.51042e-08"/>
      <joint pos="0 0 0" axis="1 0 0" type="slide"/>
      <joint pos="0 0 0" axis="0 1 0" type="slide"/>
      <joint pos="0 0 0" axis="0 0 1" type="slide"/>
    </body>
    <body name="cloth_115" pos="-0.05 -0.45 0.1">
      <inertial pos="0 0 0" mass="0.00390625" diaginertia="6.51042e-08 6.51042e-08 6.51042e-08"/>
      <joint pos="0 0 0" axis="1 0 0" type="slide"/>
      <joint pos="0 0 0" axis="0 1 0" type="slide"/>
      <joint pos="0 0 0" axis="0 0 1" type="slide"/>
    </body>
    <body name="cloth_116" pos="-0.05 -0.35 0.1">
      <inertial pos="0 0 0" mass="0.00390625" diaginertia="6.51042e-08 6.51042e-08 6.51042e-08"/>
      <joint pos="0 0 0" axis="1 0 0" type="slide"/>
      <joint pos="0 0 0" axis="0 1 0" type="slide"/>
      <joint pos="0 0 0" axis="0 0 1" type="slide"/>
    </body>
    <body name="cloth_117" pos="-0.05 -0.25 0.1">
      <inertial pos="0 0 0" mass="0.00390625" diaginertia="6.51042e-08 6.51042e-08 6.51042e-08"/>
      <joint pos="0 0 0" axis="1 0 0" type="slide"/>
      <joint pos="0 0 0" axis="0 1 0" type="slide"/>
      <joint pos="0 0 0" axis="0 0 1" type="slide"/>
    </body>
    <body name="cloth_118" pos="-0.05 -0.15 0.1">
      <inertial pos="0 0 0" mass="0.00390625" diaginertia="6.51042e-08 6.51042e-08 6.51042e-08"/>
      <joint pos="0 0 0" axis="1 0 0" type="slide"/>
      <joint pos="0 0 0" axis="0 1 0" type="slide"/>
      <joint pos="0 0 0" axis="0 0 1" type="slide"/>
    </body>
    <body name="cloth_119" pos="-0.05 -0.05 0.1">
      <inertial pos="0 0 0" mass="0.00390625" diaginertia="6.51042e-08 6.51042e-08 6.51042e-08"/>
      <joint pos="0 0 0" axis="1 0 0" type="slide"/>
      <joint pos="0 0 0" axis="0 1 0" type="slide"/>
      <joint pos="0 0 0" axis="0 0 1" type="slide"/>
    </body>
    <body name="cloth_120" pos="-0.05 0.05 0.1">
      <inertial pos="0 0 0" mass="0.00390625" diaginertia="6.51042e-08 6.51042e-08 6.51042e-08"/>
      <joint pos="0 0 0" axis="1 0 0" type="slide"/>
      <joint pos="0 0 0" axis="0 1 0" type="slide"/>
      <joint pos="0 0 0" axis="0 0 1" type="slide"/>
    </body>
    <body name="cloth_121" pos="-0.05 0.15 0.1">
      <inertial pos="0 0 0" mass="0.00390625" diaginertia="6.51042e-08 6.51042e-08 6.51042e-08"/>
      <joint pos="0 0 0" axis="1 0 0" type="slide"/>
      <joint pos="0 0 0" axis="0 1 0" type="slide"/>
      <joint pos="0 0 0" axis="0 0 1" type="slide"/>
    </body>
    <body name="cloth_122" pos="-0.05 0.25 0.1">
      <inertial pos="0 0 0" mass="0.00390625" diaginertia="6.51042e-08 6.51042e-08 6.51042e-08"/>
      <joint pos="0 0 0" axis="1 0 0" type="slide"/>
      <joint pos="0 0 0" axis="0 1 0" type="slide"/>
      <joint pos="0 0 0" axis="0 0 1" type="slide"/>
    </body>
    <body name="cloth_123" pos="-0.05 0.35 0.1">
      <inertial pos="0 0 0" mass="0.00390625" diaginertia="6.51042e-08 6.51042e-08 6.51042e-08"/>
      <joint pos="0 0 0" axis="1 0 0" type="slide"/>
      <joint pos="0 0 0" axis="0 1 0" type="slide"/>
      <joint pos="0 0 0" axis="0 0 1" type="slide"/>
    </body>
    <body name="cloth_124" pos="-0.05 0.45 0.1">
      <inertial pos="0 0 0" mass="0.00390625" diaginertia="6.51042e-08 6.51042e-08 6.51042e-08"/>
      <joint pos="0 0 0" axis="1 0 0" type="slide"/>
      <joint pos="0 0 0" axis="0 1 0" type="slide"/>
      <joint pos="0 0 0" axis="0 0 1" type="slide"/>
    </body>
    <body name="cloth_125" pos="-0.05 0.55 0.1">
      <inertial pos="0 0 0" mass="0.00390625" diaginertia="6.51042e-08 6.51042e-08 6.51042e-08"/>
      <joint pos="0 0 0" axis="1 0 0" type="slide"/>
      <joint pos="0 0 0" axis="0 1 0" type="slide"/>
      <joint pos="0 0 0" axis="0 0 1" type="slide"/>
    </body>
    <body name="cloth_126" pos="-0.05 0.65 0.1">
      <inertial pos="0 0 0" mass="0.00390625" diaginertia="6.51042e-08 6.51042e-08 6.51042e-08"/>
      <joint pos="0 0 0" axis="1 0 0" type="slide"/>
      <joint pos="0 0 0" axis="0 1 0" type="slide"/>
      <joint pos="0 0 0" axis="0 0 1" type="slide"/>
    </body>
    <body name="cloth_127" pos="-0.05 0.75 0.1">
      <inertial pos="0 0 0" mass="0.00390625" diaginertia="6.51042e-08 6.51042e-08 6.51042e-08"/>
      <joint pos="0 0 0" axis="1 0 0" type="slide"/>
      <joint pos="0 0 0" axis="0 1 0" type="slide"/>
      <joint pos="0 0 0" axis="0 0 1" type="slide"/>
    </body>
    <body name="cloth_128" pos="0.05 -0.75 0.1">
      <inertial pos="0 0 0" mass="0.00390625" diaginertia="6.51042e-08 6.51042e-08 6.51042e-08"/>
      <joint pos="0 0 0" axis="1 0 0" type="slide"/>
      <joint pos="0 0 0" axis="0 1 0" type="slide"/>
      <joint pos="0 0 0" axis="0 0 1" type="slide"/>
    </body>
    <body name="cloth_129" pos="0.05 -0.65 0.1">
      <inertial pos="0 0 0" mass="0.00390625" diaginertia="6.51042e-08 6.51042e-08 6.51042e-08"/>
      <joint pos="0 0 0" axis="1 0 0" type="slide"/>
      <joint pos="0 0 0" axis="0 1 0" type="slide"/>
      <joint pos="0 0 0" axis="0 0 1" type="slide"/>
    </body>
    <body name="cloth_130" pos="0.05 -0.55 0.1">
      <inertial pos="0 0 0" mass="0.00390625" diaginertia="6.51042e-08 6.51042e-08 6.51042e-08"/>
      <joint pos="0 0 0" axis="1 0 0" type="slide"/>
      <joint pos="0 0 0" axis="0 1 0" type="slide"/>
      <joint pos="0 0 0" axis="0 0 1" type="slide"/>
    </body>
    <body name="cloth_131" pos="0.05 -0.45 0.1">
      <inertial pos="0 0 0" mass="0.00390625" diaginertia="6.51042e-08 6.51042e-08 6.51042e-08"/>
      <joint pos="0 0 0" axis="1 0 0" type="slide"/>
      <joint pos="0 0 0" axis="0 1 0" type="slide"/>
      <joint pos="0 0 0" axis="0 0 1" type="slide"/>
    </body>
    <body name="cloth_132" pos="0.05 -0.35 0.1">
      <inertial pos="0 0 0" mass="0.00390625" diaginertia="6.51042e-08 6.51042e-08 6.51042e-08"/>
      <joint pos="0 0 0" axis="1 0 0" type="slide"/>
      <joint pos="0 0 0" axis="0 1 0" type="slide"/>
      <joint pos="0 0 0" axis="0 0 1" type="slide"/>
    </body>
    <body name="cloth_133" pos="0.05 -0.25 0.1">
      <inertial pos="0 0 0" mass="0.00390625" diaginertia="6.51042e-08 6.51042e-08 6.51042e-08"/>
      <joint pos="0 0 0" axis="1 0 0" type="slide"/>
      <joint pos="0 0 0" axis="0 1 0" type="slide"/>
      <joint pos="0 0 0" axis="0 0 1" type="slide"/>
    </body>
    <body name="cloth_134" pos="0.05 -0.15 0.1">
      <inertial pos="0 0 0" mass="0.00390625" diaginertia="6.51042e-08 6.51042e-08 6.51042e-08"/>
      <joint pos="0 0 0" axis="1 0 0" type="slide"/>
      <joint pos="0 0 0" axis="0 1 0" type="slide"/>
      <joint pos="0 0 0" axis="0 0 1" type="slide"/>
    </body>
    <body name="cloth_135" pos="0.05 -0.05 0.1">
      <inertial pos="0 0 0" mass="0.00390625" diaginertia="6.51042e-08 6.51042e-08 6.51042e-08"/>
      <joint pos="0 0 0" axis="1 0 0" type="slide"/>
      <joint pos="0 0 0" axis="0 1 0" type="slide"/>
      <joint pos="0 0 0" axis="0 0 1" type="slide"/>
    </body>
    <body name="cloth_136" pos="0.05 0.05 0.1">
      <inertial pos="0 0 0" mass="0.00390625" diaginertia="6.51042e-08 6.51042e-08 6.51042e-08"/>
      <joint pos="0 0 0" axis="1 0 0" type="slide"/>
      <joint pos="0 0 0" axis="0 1 0" type="slide"/>
      <joint pos="0 0 0" axis="0 0 1" type="slide"/>
    </body>
    <body name="cloth_137" pos="0.05 0.15 0.1">
      <inertial pos="0 0 0" mass="0.00390625" diaginertia="6.51042e-08 6.51042e-08 6.51042e-08"/>
      <joint pos="0 0 0" axis="1 0 0" type="slide"/>
      <joint pos="0 0 0" axis="0 1 0" type="slide"/>
      <joint pos="0 0 0" axis="0 0 1" type="slide"/>
    </body>
    <body name="cloth_138" pos="0.05 0.25 0.1">
      <inertial pos="0 0 0" mass="0.00390625" diaginertia="6.51042e-08 6.51042e-08 6.51042e-08"/>
      <joint pos="0 0 0" axis="1 0 0" type="slide"/>
      <joint pos="0 0 0" axis="0 1 0" type="slide"/>
      <joint pos="0 0 0" axis="0 0 1" type="slide"/>
    </body>
    <body name="cloth_139" pos="0.05 0.35 0.1">
      <inertial pos="0 0 0" mass="0.00390625" diaginertia="6.51042e-08 6.51042e-08 6.51042e-08"/>
      <joint pos="0 0 0" axis="1 0 0" type="slide"/>
      <joint pos="0 0 0" axis="0 1 0" type="slide"/>
      <joint pos="0 0 0" axis="0 0 1" type="slide"/>
    </body>
    <body name="cloth_140" pos="0.05 0.45 0.1">
      <inertial pos="0 0 0" mass="0.00390625" diaginertia="6.51042e-08 6.51042e-08 6.51042e-08"/>
      <joint pos="0 0 0" axis="1 0 0" type="slide"/>
      <joint pos="0 0 0" axis="0 1 0" type="slide"/>
      <joint pos="0 0 0" axis="0 0 1" type="slide"/>
    </body>
    <body name="cloth_141" pos="0.05 0.55 0.1">
      <inertial pos="0 0 0" mass="0.00390625" diaginertia="6.51042e-08 6.51042e-08 6.51042e-08"/>
      <joint pos="0 0 0" axis="1 0 0" type="slide"/>
      <joint pos="0 0 0" axis="0 1 0" type="slide"/>
      <joint pos="0 0 0" axis="0 0 1" type="slide"/>
    </body>
    <body name="cloth_142" pos="0.05 0.65 0.1">
      <inertial pos="0 0 0" mass="0.00390625" diaginertia="6.51042e-08 6.51042e-08 6.51042e-08"/>
      <joint pos="0 0 0" axis="1 0 0" type="slide"/>
      <joint pos="0 0 0" axis="0 1 0" type="slide"/>
      <joint pos="0 0 0" axis="0 0 1" type="slide"/>
    </body>
    <body name="cloth_143" pos="0.05 0.75 0.1">
      <inertial pos="0 0 0" mass="0.00390625" diaginertia="6.51042e-08 6.51042e-08 6.51042e-08"/>
      <joint pos="0 0 0" axis="1 0 0" type="slide"/>
      <joint pos="0 0 0" axis="0 1 0" type="slide"/>
      <joint pos="0 0 0" axis="0 0 1" type="slide"/>
    </body>
    <body name="cloth_144" pos="0.15 -0.75 0.1">
      <inertial pos="0 0 0" mass="0.00390625" diaginertia="6.51042e-08 6.51042e-08 6.51042e-08"/>
      <joint pos="0 0 0" axis="1 0 0" type="slide"/>
      <joint pos="0 0 0" axis="0 1 0" type="slide"/>
      <joint pos="0 0 0" axis="0 0 1" type="slide"/>
    </body>
    <body name="cloth_145" pos="0.15 -0.65 0.1">
      <inertial pos="0 0 0" mass="0.00390625" diaginertia="6.51042e-08 6.51042e-08 6.51042e-08"/>
      <joint pos="0 0 0" axis="1 0 0" type="slide"/>
      <joint pos="0 0 0" axis="0 1 0" type="slide"/>
      <joint pos="0 0 0" axis="0 0 1" type="slide"/>
    </body>
    <body name="cloth_146" pos="0.15 -0.55 0.1">
      <inertial pos="0 0 0" mass="0.00390625" diaginertia="6.51042e-08 6.51042e-08 6.51042e-08"/>
      <joint pos="0 0 0" axis="1 0 0" type="slide"/>
      <joint pos="0 0 0" axis="0 1 0" type="slide"/>
      <joint pos="0 0 0" axis="0 0 1" type="slide"/>
    </body>
    <body name="cloth_147" pos="0.15 -0.45 0.1">
      <inertial pos="0 0 0" mass="0.00390625" diaginertia="6.51042e-08 6.51042e-08 6.51042e-08"/>
      <joint pos="0 0 0" axis="1 0 0" type="slide"/>
      <joint pos="0 0 0" axis="0 1 0" type="slide"/>
      <joint pos="0 0 0" axis="0 0 1" type="slide"/>
    </body>
    <body name="cloth_148" pos="0.15 -0.35 0.1">
      <inertial pos="0 0 0" mass="0.00390625" diaginertia="6.51042e-08 6.51042e-08 6.51042e-08"/>
      <joint pos="0 0 0" axis="1 0 0" type="slide"/>
      <joint pos="0 0 0" axis="0 1 0" type="slide"/>
      <joint pos="0 0 0" axis="0 0 1" type="slide"/>
    </body>
    <body name="cloth_149" pos="0.15 -0.25 0.1">
      <inertial pos="0 0 0" mass="0.00390625" diaginertia="6.51042e-08 6.51042e-08 6.51042e-08"/>
      <joint pos="0 0 0" axis="1 0 0" type="slide"/>
      <joint pos="0 0 0" axis="0 1 0" type="slide"/>
      <joint pos="0 0 0" axis="0 0 1" type="slide"/>
    </body>
    <body name="cloth_150" pos="0.15 -0.15 0.1">
      <inertial pos="0 0 0" mass="0.00390625" diaginertia="6.51042e-08 6.51042e-08 6.51042e-08"/>
      <joint pos="0 0 0" axis="1 0 0" type="slide"/>
      <joint pos="0 0 0" axis="0 1 0" type="slide"/>
      <joint pos="0 0 0" axis="0 0 1" type="slide"/>
    </body>
    <body name="cloth_151" pos="0.15 -0.05 0.1">
      <inertial pos="0 0 0" mass="0.00390625" diaginertia="6.51042e-08 6.51042e-08 6.51042e-08"/>
      <joint pos="0 0 0" axis="1 0 0" type="slide"/>
      <joint pos="0 0 0" axis="0 1 0" type="slide"/>
      <joint pos="0 0 0" axis="0 0 1" type="slide"/>
    </body>
    <body name="cloth_152" pos="0.15 0.05 0.1">
      <inertial pos="0 0 0" mass="0.00390625" diaginertia="6.51042e-08 6.51042e-08 6.51042e-08"/>
      <joint pos="0 0 0" axis="1 0 0" type="slide"/>
      <joint pos="0 0 0" axis="0 1 0" type="slide"/>
      <joint pos="0 0 0" axis="0 0 1" type="slide"/>
    </body>
    <body name="cloth_153" pos="0.15 0.15 0.1">
      <inertial pos="0 0 0" mass="0.00390625" diaginertia="6.51042e-08 6.51042e-08 6.51042e-08"/>
      <joint pos="0 0 0" axis="1 0 0" type="slide"/>
      <joint pos="0 0 0" axis="0 1 0" type="slide"/>
      <joint pos="0 0 0" axis="0 0 1" type="slide"/>
    </body>
    <body name="cloth_154" pos="0.15 0.25 0.1">
      <inertial pos="0 0 0" mass="0.00390625" diaginertia="6.51042e-08 6.51042e-08 6.51042e-08"/>
      <joint pos="0 0 0" axis="1 0 0" type="slide"/>
      <joint pos="0 0 0" axis="0 1 0" type="slide"/>
      <joint pos="0 0 0" axis="0 0 1" type="slide"/>
    </body>
    <body name="cloth_155" pos="0.15 0.35 0.1">
      <inertial pos="0 0 0" mass="0.00390625" diaginertia="6.51042e-08 6.51042e-08 6.51042e-08"/>
      <joint pos="0 0 0" axis="1 0 0" type="slide"/>
      <joint pos="0 0 0" axis="0 1 0" type="slide"/>
      <joint pos="0 0 0" axis="0 0 1" type="slide"/>
    </body>
    <body name="cloth_156" pos="0.15 0.45 0.1">
      <inertial pos="0 0 0" mass="0.00390625" diaginertia="6.51042e-08 6.51042e-08 6.51042e-08"/>
      <joint pos="0 0 0" axis="1 0 0" type="slide"/>
      <joint pos="0 0 0" axis="0 1 0" type="slide"/>
      <joint pos="0 0 0" axis="0 0 1" type="slide"/>
    </body>
    <body name="cloth_157" pos="0.15 0.55 0.1">
      <inertial pos="0 0 0" mass="0.00390625" diaginertia="6.51042e-08 6.51042e-08 6.51042e-08"/>
      <joint pos="0 0 0" axis="1 0 0" type="slide"/>
      <joint pos="0 0 0" axis="0 1 0" type="slide"/>
      <joint pos="0 0 0" axis="0 0 1" type="slide"/>
    </body>
    <body name="cloth_158" pos="0.15 0.65 0.1">
      <inertial pos="0 0 0" mass="0.00390625" diaginertia="6.51042e-08 6.51042e-08 6.51042e-08"/>
      <joint pos="0 0 0" axis="1 0 0" type="slide"/>
      <joint pos="0 0 0" axis="0 1 0" type="slide"/>
      <joint pos="0 0 0" axis="0 0 1" type="slide"/>
    </body>
    <body name="cloth_159" pos="0.15 0.75 0.1">
      <inertial pos="0 0 0" mass="0.00390625" diaginertia="6.51042e-08 6.51042e-08 6.51042e-08"/>
      <joint pos="0 0 0" axis="1 0 0" type="slide"/>
      <joint pos="0 0 0" axis="0 1 0" type="slide"/>
      <joint pos="0 0 0" axis="0 0 1" type="slide"/>
    </body>
    <body name="cloth_160" pos="0.25 -0.75 0.1">
      <inertial pos="0 0 0" mass="0.00390625" diaginertia="6.51042e-08 6.51042e-08 6.51042e-08"/>
      <joint pos="0 0 0" axis="1 0 0" type="slide"/>
      <joint pos="0 0 0" axis="0 1 0" type="slide"/>
      <joint pos="0 0 0" axis="0 0 1" type="slide"/>
    </body>
    <body name="cloth_161" pos="0.25 -0.65 0.1">
      <inertial pos="0 0 0" mass="0.00390625" diaginertia="6.51042e-08 6.51042e-08 6.51042e-08"/>
      <joint pos="0 0 0" axis="1 0 0" type="slide"/>
      <joint pos="0 0 0" axis="0 1 0" type="slide"/>
      <joint pos="0 0 0" axis="0 0 1" type="slide"/>
    </body>
    <body name="cloth_162" pos="0.25 -0.55 0.1">
      <inertial pos="0 0 0" mass="0.00390625" diaginertia="6.51042e-08 6.51042e-08 6.51042e-08"/>
      <joint pos="0 0 0" axis="1 0 0" type="slide"/>
      <joint pos="0 0 0" axis="0 1 0" type="slide"/>
      <joint pos="0 0 0" axis="0 0 1" type="slide"/>
    </body>
    <body name="cloth_163" pos="0.25 -0.45 0.1">
      <inertial pos="0 0 0" mass="0.00390625" diaginertia="6.51042e-08 6.51042e-08 6.51042e-08"/>
      <joint pos="0 0 0" axis="1 0 0" type="slide"/>
      <joint pos="0 0 0" axis="0 1 0" type="slide"/>
      <joint pos="0 0 0" axis="0 0 1" type="slide"/>
    </body>
    <body name="cloth_164" pos="0.25 -0.35 0.1">
      <inertial pos="0 0 0" mass="0.00390625" diaginertia="6.51042e-08 6.51042e-08 6.51042e-08"/>
      <joint pos="0 0 0" axis="1 0 0" type="slide"/>
      <joint pos="0 0 0" axis="0 1 0" type="slide"/>
      <joint pos="0 0 0" axis="0 0 1" type="slide"/>
    </body>
    <body name="cloth_165" pos="0.25 -0.25 0.1">
      <inertial pos="0 0 0" mass="0.00390625" diaginertia="6.51042e-08 6.51042e-08 6.51042e-08"/>
      <joint pos="0 0 0" axis="1 0 0" type="slide"/>
      <joint pos="0 0 0" axis="0 1 0" type="slide"/>
      <joint pos="0 0 0" axis="0 0 1" type="slide"/>
    </body>
    <body name="cloth_166" pos="0.25 -0.15 0.1">
      <inertial pos="0 0 0" mass="0.00390625" diaginertia="6.51042e-08 6.51042e-08 6.51042e-08"/>
      <joint pos="0 0 0" axis="1 0 0" type="slide"/>
      <joint pos="0 0 0" axis="0 1 0" type="slide"/>
      <joint pos="0 0 0" axis="0 0 1" type="slide"/>
    </body>
    <body name="cloth_167" pos="0.25 -0.05 0.1">
      <inertial pos="0 0 0" mass="0.00390625" diaginertia="6.51042e-08 6.51042e-08 6.51042e-08"/>
      <joint pos="0 0 0" axis="1 0 0" type="slide"/>
      <joint pos="0 0 0" axis="0 1 0" type="slide"/>
      <joint pos="0 0 0" axis="0 0 1" type="slide"/>
    </body>
    <body name="cloth_168" pos="0.25 0.05 0.1">
      <inertial pos="0 0 0" mass="0.00390625" diaginertia="6.51042e-08 6.51042e-08 6.51042e-08"/>
      <joint pos="0 0 0" axis="1 0 0" type="slide"/>
      <joint pos="0 0 0" axis="0 1 0" type="slide"/>
      <joint pos="0 0 0" axis="0 0 1" type="slide"/>
    </body>
    <body name="cloth_169" pos="0.25 0.15 0.1">
      <inertial pos="0 0 0" mass="0.00390625" diaginertia="6.51042e-08 6.51042e-08 6.51042e-08"/>
      <joint pos="0 0 0" axis="1 0 0" type="slide"/>
      <joint pos="0 0 0" axis="0 1 0" type="slide"/>
      <joint pos="0 0 0" axis="0 0 1" type="slide"/>
    </body>
    <body name="cloth_170" pos="0.25 0.25 0.1">
      <inertial pos="0 0 0" mass="0.00390625" diaginertia="6.51042e-08 6.51042e-08 6.51042e-08"/>
      <joint pos="0 0 0" axis="1 0 0" type="slide"/>
      <joint pos="0 0 0" axis="0 1 0" type="slide"/>
      <joint pos="0 0 0" axis="0 0 1" type="slide"/>
    </body>
    <body name="cloth_171" pos="0.25 0.35 0.1">
      <inertial pos="0 0 0" mass="0.00390625" diaginertia="6.51042e-08 6.51042e-08 6.51042e-08"/>
      <joint pos="0 0 0" axis="1 0 0" type="slide"/>
      <joint pos="0 0 0" axis="0 1 0" type="slide"/>
      <joint pos="0 0 0" axis="0 0 1" type="slide"/>
    </body>
    <body name="cloth_172" pos="0.25 0.45 0.1">
      <inertial pos="0 0 0" mass="0.00390625" diaginertia="6.51042e-08 6.51042e-08 6.51042e-08"/>
      <joint pos="0 0 0" axis="1 0 0" type="slide"/>
      <joint pos="0 0 0" axis="0 1 0" type="slide"/>
      <joint pos="0 0 0" axis="0 0 1" type="slide"/>
    </body>
    <body name="cloth_173" pos="0.25 0.55 0.1">
      <inertial pos="0 0 0" mass="0.00390625" diaginertia="6.51042e-08 6.51042e-08 6.51042e-08"/>
      <joint pos="0 0 0" axis="1 0 0" type="slide"/>
      <joint pos="0 0 0" axis="0 1 0" type="slide"/>
      <joint pos="0 0 0" axis="0 0 1" type="slide"/>
    </body>
    <body name="cloth_174" pos="0.25 0.65 0.1">
      <inertial pos="0 0 0" mass="0.00390625" diaginertia="6.51042e-08 6.51042e-08 6.51042e-08"/>
      <joint pos="0 0 0" axis="1 0 0" type="slide"/>
      <joint pos="0 0 0" axis="0 1 0" type="slide"/>
      <joint pos="0 0 0" axis="0 0 1" type="slide"/>
    </body>
    <body name="cloth_175" pos="0.25 0.75 0.1">
      <inertial pos="0 0 0" mass="0.00390625" diaginertia="6.51042e-08 6.51042e-08 6.51042e-08"/>
      <joint pos="0 0 0" axis="1 0 0" type="slide"/>
      <joint pos="0 0 0" axis="0 1 0" type="slide"/>
      <joint pos="0 0 0" axis="0 0 1" type="slide"/>
    </body>
    <body name="cloth_176" pos="0.35 -0.75 0.1">
      <inertial pos="0 0 0" mass="0.00390625" diaginertia="6.51042e-08 6.51042e-08 6.51042e-08"/>
      <joint pos="0 0 0" axis="1 0 0" type="slide"/>
      <joint pos="0 0 0" axis="0 1 0" type="slide"/>
      <joint pos="0 0 0" axis="0 0 1" type="slide"/>
    </body>
    <body name="cloth_177" pos="0.35 -0.65 0.1">
      <inertial pos="0 0 0" mass="0.00390625" diaginertia="6.51042e-08 6.51042e-08 6.51042e-08"/>
      <joint pos="0 0 0" axis="1 0 0" type="slide"/>
      <joint pos="0 0 0" axis="0 1 0" type="slide"/>
      <joint pos="0 0 0" axis="0 0 1" type="slide"/>
    </body>
    <body name="cloth_178" pos="0.35 -0.55 0.1">
      <inertial pos="0 0 0" mass="0.00390625" diaginertia="6.51042e-08 6.51042e-08 6.51042e-08"/>
      <joint pos="0 0 0" axis="1 0 0" type="slide"/>
      <joint pos="0 0 0" axis="0 1 0" type="slide"/>
      <joint pos="0 0 0" axis="0 0 1" type="slide"/>
    </body>
    <body name="cloth_179" pos="0.35 -0.45 0.1">
      <inertial pos="0 0 0" mass="0.00390625" diaginertia="6.51042e-08 6.51042e-08 6.51042e-08"/>
      <joint pos="0 0 0" axis="1 0 0" type="slide"/>
      <joint pos="0 0 0" axis="0 1 0" type="slide"/>
      <joint pos="0 0 0" axis="0 0 1" type="slide"/>
    </body>
    <body name="cloth_180" pos="0.35 -0.35 0.1">
      <inertial pos="0 0 0" mass="0.00390625" diaginertia="6.51042e-08 6.51042e-08 6.51042e-08"/>
      <joint pos="0 0 0" axis="1 0 0" type="slide"/>
      <joint pos="0 0 0" axis="0 1 0" type="slide"/>
      <joint pos="0 0 0" axis="0 0 1" type="slide"/>
    </body>
    <body name="cloth_181" pos="0.35 -0.25 0.1">
      <inertial pos="0 0 0" mass="0.00390625" diaginertia="6.51042e-08 6.51042e-08 6.51042e-08"/>
      <joint pos="0 0 0" axis="1 0 0" type="slide"/>
      <joint pos="0 0 0" axis="0 1 0" type="slide"/>
      <joint pos="0 0 0" axis="0 0 1" type="slide"/>
    </body>
    <body name="cloth_182" pos="0.35 -0.15 0.1">
      <inertial pos="0 0 0" mass="0.00390625" diaginertia="6.51042e-08 6.51042e-08 6.51042e-08"/>
      <joint pos="0 0 0" axis="1 0 0" type="slide"/>
      <joint pos="0 0 0" axis="0 1 0" type="slide"/>
      <joint pos="0 0 0" axis="0 0 1" type="slide"/>
    </body>
    <body name="cloth_183" pos="0.35 -0.05 0.1">
      <inertial pos="0 0 0" mass="0.00390625" diaginertia="6.51042e-08 6.51042e-08 6.51042e-08"/>
      <joint pos="0 0 0" axis="1 0 0" type="slide"/>
      <joint pos="0 0 0" axis="0 1 0" type="slide"/>
      <joint pos="0 0 0" axis="0 0 1" type="slide"/>
    </body>
    <body name="cloth_184" pos="0.35 0.05 0.1">
      <inertial pos="0 0 0" mass="0.00390625" diaginertia="6.51042e-08 6.51042e-08 6.51042e-08"/>
      <joint pos="0 0 0" axis="1 0 0" type="slide"/>
      <joint pos="0 0 0" axis="0 1 0" type="slide"/>
      <joint pos="0 0 0" axis="0 0 1" type="slide"/>
    </body>
    <body name="cloth_185" pos="0.35 0.15 0.1">
      <inertial pos="0 0 0" mass="0.00390625" diaginertia="6.51042e-08 6.51042e-08 6.51042e-08"/>
      <joint pos="0 0 0" axis="1 0 0" type="slide"/>
      <joint pos="0 0 0" axis="0 1 0" type="slide"/>
      <joint pos="0 0 0" axis="0 0 1" type="slide"/>
    </body>
    <body name="cloth_186" pos="0.35 0.25 0.1">
      <inertial pos="0 0 0" mass="0.00390625" diaginertia="6.51042e-08 6.51042e-08 6.51042e-08"/>
      <joint pos="0 0 0" axis="1 0 0" type="slide"/>
      <joint pos="0 0 0" axis="0 1 0" type="slide"/>
      <joint pos="0 0 0" axis="0 0 1" type="slide"/>
    </body>
    <body name="cloth_187" pos="0.35 0.35 0.1">
      <inertial pos="0 0 0" mass="0.00390625" diaginertia="6.51042e-08 6.51042e-08 6.51042e-08"/>
      <joint pos="0 0 0" axis="1 0 0" type="slide"/>
      <joint pos="0 0 0" axis="0 1 0" type="slide"/>
      <joint pos="0 0 0" axis="0 0 1" type="slide"/>
    </body>
    <body name="cloth_188" pos="0.35 0.45 0.1">
      <inertial pos="0 0 0" mass="0.00390625" diaginertia="6.51042e-08 6.51042e-08 6.51042e-08"/>
      <joint pos="0 0 0" axis="1 0 0" type="slide"/>
      <joint pos="0 0 0" axis="0 1 0" type="slide"/>
      <joint pos="0 0 0" axis="0 0 1" type="slide"/>
    </body>
    <body name="cloth_189" pos="0.35 0.55 0.1">
      <inertial pos="0 0 0" mass="0.00390625" diaginertia="6.51042e-08 6.51042e-08 6.51042e-08"/>
      <joint pos="0 0 0" axis="1 0 0" type="slide"/>
      <joint pos="0 0 0" axis="0 1 0" type="slide"/>
      <joint pos="0 0 0" axis="0 0 1" type="slide"/>
    </body>
    <body name="cloth_190" pos="0.35 0.65 0.1">
      <inertial pos="0 0 0" mass="0.00390625" diaginertia="6.51042e-08 6.51042e-08 6.51042e-08"/>
      <joint pos="0 0 0" axis="1 0 0" type="slide"/>
      <joint pos="0 0 0" axis="0 1 0" type="slide"/>
      <joint pos="0 0 0" axis="0 0 1" type="slide"/>
    </body>
    <body name="cloth_191" pos="0.35 0.75 0.1">
      <inertial pos="0 0 0" mass="0.00390625" diaginertia="6.51042e-08 6.51042e-08 6.51042e-08"/>
      <joint pos="0 0 0" axis="1 0 0" type="slide"/>
      <joint pos="0 0 0" axis="0 1 0" type="slide"/>
      <joint pos="0 0 0" axis="0 0 1" type="slide"/>
    </body>
    <body name="cloth_192" pos="0.45 -0.75 0.1">
      <inertial pos="0 0 0" mass="0.00390625" diaginertia="6.51042e-08 6.51042e-08 6.51042e-08"/>
      <joint pos="0 0 0" axis="1 0 0" type="slide"/>
      <joint pos="0 0 0" axis="0 1 0" type="slide"/>
      <joint pos="0 0 0" axis="0 0 1" type="slide"/>
    </body>
    <body name="cloth_193" pos="0.45 -0.65 0.1">
      <inertial pos="0 0 0" mass="0.00390625" diaginertia="6.51042e-08 6.51042e-08 6.51042e-08"/>
      <joint pos="0 0 0" axis="1 0 0" type="slide"/>
      <joint pos="0 0 0" axis="0 1 0" type="slide"/>
      <joint pos="0 0 0" axis="0 0 1" type="slide"/>
    </body>
    <body name="cloth_194" pos="0.45 -0.55 0.1">
      <inertial pos="0 0 0" mass="0.00390625" diaginertia="6.51042e-08 6.51042e-08 6.51042e-08"/>
      <joint pos="0 0 0" axis="1 0 0" type="slide"/>
      <joint pos="0 0 0" axis="0 1 0" type="slide"/>
      <joint pos="0 0 0" axis="0 0 1" type="slide"/>
    </body>
    <body name="cloth_195" pos="0.45 -0.45 0.1">
      <inertial pos="0 0 0" mass="0.00390625" diaginertia="6.51042e-08 6.51042e-08 6.51042e-08"/>
      <joint pos="0 0 0" axis="1 0 0" type="slide"/>
      <joint pos="0 0 0" axis="0 1 0" type="slide"/>
      <joint pos="0 0 0" axis="0 0 1" type="slide"/>
    </body>
    <body name="cloth_196" pos="0.45 -0.35 0.1">
      <inertial pos="0 0 0" mass="0.00390625" diaginertia="6.51042e-08 6.51042e-08 6.51042e-08"/>
      <joint pos="0 0 0" axis="1 0 0" type="slide"/>
      <joint pos="0 0 0" axis="0 1 0" type="slide"/>
      <joint pos="0 0 0" axis="0 0 1" type="slide"/>
    </body>
    <body name="cloth_197" pos="0.45 -0.25 0.1">
      <inertial pos="0 0 0" mass="0.00390625" diaginertia="6.51042e-08 6.51042e-08 6.51042e-08"/>
      <joint pos="0 0 0" axis="1 0 0" type="slide"/>
      <joint pos="0 0 0" axis="0 1 0" type="slide"/>
      <joint pos="0 0 0" axis="0 0 1" type="slide"/>
    </body>
    <body name="cloth_198" pos="0.45 -0.15 0.1">
      <inertial pos="0 0 0" mass="0.00390625" diaginertia="6.51042e-08 6.51042e-08 6.51042e-08"/>
      <joint pos="0 0 0" axis="1 0 0" type="slide"/>
      <joint pos="0 0 0" axis="0 1 0" type="slide"/>
      <joint pos="0 0 0" axis="0 0 1" type="slide"/>
    </body>
    <body name="cloth_199" pos="0.45 -0.05 0.1">
      <inertial pos="0 0 0" mass="0.00390625" diaginertia="6.51042e-08 6.51042e-08 6.51042e-08"/>
      <joint pos="0 0 0" axis="1 0 0" type="slide"/>
      <joint pos="0 0 0" axis="0 1 0" type="slide"/>
      <joint pos="0 0 0" axis="0 0 1" type="slide"/>
    </body>
    <body name="cloth_200" pos="0.45 0.05 0.1">
      <inertial pos="0 0 0" mass="0.00390625" diaginertia="6.51042e-08 6.51042e-08 6.51042e-08"/>
      <joint pos="0 0 0" axis="1 0 0" type="slide"/>
      <joint pos="0 0 0" axis="0 1 0" type="slide"/>
      <joint pos="0 0 0" axis="0 0 1" type="slide"/>
    </body>
    <body name="cloth_201" pos="0.45 0.15 0.1">
      <inertial pos="0 0 0" mass="0.00390625" diaginertia="6.51042e-08 6.51042e-08 6.51042e-08"/>
      <joint pos="0 0 0" axis="1 0 0" type="slide"/>
      <joint pos="0 0 0" axis="0 1 0" type="slide"/>
      <joint pos="0 0 0" axis="0 0 1" type="slide"/>
    </body>
    <body name="cloth_202" pos="0.45 0.25 0.1">
      <inertial pos="0 0 0" mass="0.00390625" diaginertia="6.51042e-08 6.51042e-08 6.51042e-08"/>
      <joint pos="0 0 0" axis="1 0 0" type="slide"/>
      <joint pos="0 0 0" axis="0 1 0" type="slide"/>
      <joint pos="0 0 0" axis="0 0 1" type="slide"/>
    </body>
    <body name="cloth_203" pos="0.45 0.35 0.1">
      <inertial pos="0 0 0" mass="0.00390625" diaginertia="6.51042e-08 6.51042e-08 6.51042e-08"/>
      <joint pos="0 0 0" axis="1 0 0" type="slide"/>
      <joint pos="0 0 0" axis="0 1 0" type="slide"/>
      <joint pos="0 0 0" axis="0 0 1" type="slide"/>
    </body>
    <body name="cloth_204" pos="0.45 0.45 0.1">
      <inertial pos="0 0 0" mass="0.00390625" diaginertia="6.51042e-08 6.51042e-08 6.51042e-08"/>
      <joint pos="0 0 0" axis="1 0 0" type="slide"/>
      <joint pos="0 0 0" axis="0 1 0" type="slide"/>
      <joint pos="0 0 0" axis="0 0 1" type="slide"/>
    </body>
    <body name="cloth_205" pos="0.45 0.55 0.1">
      <inertial pos="0 0 0" mass="0.00390625" diaginertia="6.51042e-08 6.51042e-08 6.51042e-08"/>
      <joint pos="0 0 0" axis="1 0 0" type="slide"/>
      <joint pos="0 0 0" axis="0 1 0" type="slide"/>
      <joint pos="0 0 0" axis="0 0 1" type="slide"/>
    </body>
    <body name="cloth_206" pos="0.45 0.65 0.1">
      <inertial pos="0 0 0" mass="0.00390625" diaginertia="6.51042e-08 6.51042e-08 6.51042e-08"/>
      <joint pos="0 0 0" axis="1 0 0" type="slide"/>
      <joint pos="0 0 0" axis="0 1 0" type="slide"/>
      <joint pos="0 0 0" axis="0 0 1" type="slide"/>
    </body>
    <body name="cloth_207" pos="0.45 0.75 0.1">
      <inertial pos="0 0 0" mass="0.00390625" diaginertia="6.51042e-08 6.51042e-08 6.51042e-08"/>
      <joint pos="0 0 0" axis="1 0 0" type="slide"/>
      <joint pos="0 0 0" axis="0 1 0" type="slide"/>
      <joint pos="0 0 0" axis="0 0 1" type="slide"/>
    </body>
    <body name="cloth_208" pos="0.55 -0.75 0.1">
      <inertial pos="0 0 0" mass="0.00390625" diaginertia="6.51042e-08 6.51042e-08 6.51042e-08"/>
      <joint pos="0 0 0" axis="1 0 0" type="slide"/>
      <joint pos="0 0 0" axis="0 1 0" type="slide"/>
      <joint pos="0 0 0" axis="0 0 1" type="slide"/>
    </body>
    <body name="cloth_209" pos="0.55 -0.65 0.1">
      <inertial pos="0 0 0" mass="0.00390625" diaginertia="6.51042e-08 6.51042e-08 6.51042e-08"/>
      <joint pos="0 0 0" axis="1 0 0" type="slide"/>
      <joint pos="0 0 0" axis="0 1 0" type="slide"/>
      <joint pos="0 0 0" axis="0 0 1" type="slide"/>
    </body>
    <body name="cloth_210" pos="0.55 -0.55 0.1">
      <inertial pos="0 0 0" mass="0.00390625" diaginertia="6.51042e-08 6.51042e-08 6.51042e-08"/>
      <joint pos="0 0 0" axis="1 0 0" type="slide"/>
      <joint pos="0 0 0" axis="0 1 0" type="slide"/>
      <joint pos="0 0 0" axis="0 0 1" type="slide"/>
    </body>
    <body name="cloth_211" pos="0.55 -0.45 0.1">
      <inertial pos="0 0 0" mass="0.00390625" diaginertia="6.51042e-08 6.51042e-08 6.51042e-08"/>
      <joint pos="0 0 0" axis="1 0 0" type="slide"/>
      <joint pos="0 0 0" axis="0 1 0" type="slide"/>
      <joint pos="0 0 0" axis="0 0 1" type="slide"/>
    </body>
    <body name="cloth_212" pos="0.55 -0.35 0.1">
      <inertial pos="0 0 0" mass="0.00390625" diaginertia="6.51042e-08 6.51042e-08 6.51042e-08"/>
      <joint pos="0 0 0" axis="1 0 0" type="slide"/>
      <joint pos="0 0 0" axis="0 1 0" type="slide"/>
      <joint pos="0 0 0" axis="0 0 1" type="slide"/>
    </body>
    <body name="cloth_213" pos="0.55 -0.25 0.1">
      <inertial pos="0 0 0" mass="0.00390625" diaginertia="6.51042e-08 6.51042e-08 6.51042e-08"/>
      <joint pos="0 0 0" axis="1 0 0" type="slide"/>
      <joint pos="0 0 0" axis="0 1 0" type="slide"/>
      <joint pos="0 0 0" axis="0 0 1" type="slide"/>
    </body>
    <body name="cloth_214" pos="0.55 -0.15 0.1">
      <inertial pos="0 0 0" mass="0.00390625" diaginertia="6.51042e-08 6.51042e-08 6.51042e-08"/>
      <joint pos="0 0 0" axis="1 0 0" type="slide"/>
      <joint pos="0 0 0" axis="0 1 0" type="slide"/>
      <joint pos="0 0 0" axis="0 0 1" type="slide"/>
    </body>
    <body name="cloth_215" pos="0.55 -0.05 0.1">
      <inertial pos="0 0 0" mass="0.00390625" diaginertia="6.51042e-08 6.51042e-08 6.51042e-08"/>
      <joint pos="0 0 0" axis="1 0 0" type="slide"/>
      <joint pos="0 0 0" axis="0 1 0" type="slide"/>
      <joint pos="0 0 0" axis="0 0 1" type="slide"/>
    </body>
    <body name="cloth_216" pos="0.55 0.05 0.1">
      <inertial pos="0 0 0" mass="0.00390625" diaginertia="6.51042e-08 6.51042e-08 6.51042e-08"/>
      <joint pos="0 0 0" axis="1 0 0" type="slide"/>
      <joint pos="0 0 0" axis="0 1 0" type="slide"/>
      <joint pos="0 0 0" axis="0 0 1" type="slide"/>
    </body>
    <body name="cloth_217" pos="0.55 0.15 0.1">
      <inertial pos="0 0 0" mass="0.00390625" diaginertia="6.51042e-08 6.51042e-08 6.51042e-08"/>
      <joint pos="0 0 0" axis="1 0 0" type="slide"/>
      <joint pos="0 0 0" axis="0 1 0" type="slide"/>
      <joint pos="0 0 0" axis="0 0 1" type="slide"/>
    </body>
    <body name="cloth_218" pos="0.55 0.25 0.1">
      <inertial pos="0 0 0" mass="0.00390625" diaginertia="6.51042e-08 6.51042e-08 6.51042e-08"/>
      <joint pos="0 0 0" axis="1 0 0" type="slide"/>
      <joint pos="0 0 0" axis="0 1 0" type="slide"/>
      <joint pos="0 0 0" axis="0 0 1" type="slide"/>
    </body>
    <body name="cloth_219" pos="0.55 0.35 0.1">
      <inertial pos="0 0 0" mass="0.00390625" diaginertia="6.51042e-08 6.51042e-08 6.51042e-08"/>
      <joint pos="0 0 0" axis="1 0 0" type="slide"/>
      <joint pos="0 0 0" axis="0 1 0" type="slide"/>
      <joint pos="0 0 0" axis="0 0 1" type="slide"/>
    </body>
    <body name="cloth_220" pos="0.55 0.45 0.1">
      <inertial pos="0 0 0" mass="0.00390625" diaginertia="6.51042e-08 6.51042e-08 6.51042e-08"/>
      <joint pos="0 0 0" axis="1 0 0" type="slide"/>
      <joint pos="0 0 0" axis="0 1 0" type="slide"/>
      <joint pos="0 0 0" axis="0 0 1" type="slide"/>
    </body>
    <body name="cloth_221" pos="0.55 0.55 0.1">
      <inertial pos="0 0 0" mass="0.00390625" diaginertia="6.51042e-08 6.51042e-08 6.51042e-08"/>
      <joint pos="0 0 0" axis="1 0 0" type="slide"/>
      <joint pos="0 0 0" axis="0 1 0" type="slide"/>
      <joint pos="0 0 0" axis="0 0 1" type="slide"/>
    </body>
    <body name="cloth_222" pos="0.55 0.65 0.1">
      <inertial pos="0 0 0" mass="0.00390625" diaginertia="6.51042e-08 6.51042e-08 6.51042e-08"/>
      <joint pos="0 0 0" axis="1 0 0" type="slide"/>
      <joint pos="0 0 0" axis="0 1 0" type="slide"/>
      <joint pos="0 0 0" axis="0 0 1" type="slide"/>
    </body>
    <body name="cloth_223" pos="0.55 0.75 0.1">
      <inertial pos="0 0 0" mass="0.00390625" diaginertia="6.51042e-08 6.51042e-08 6.51042e-08"/>
      <joint pos="0 0 0" axis="1 0 0" type="slide"/>
      <joint pos="0 0 0" axis="0 1 0" type="slide"/>
      <joint pos="0 0 0" axis="0 0 1" type="slide"/>
    </body>
    <body name="cloth_224" pos="0.65 -0.75 0.1">
      <inertial pos="0 0 0" mass="0.00390625" diaginertia="6.51042e-08 6.51042e-08 6.51042e-08"/>
      <joint pos="0 0 0" axis="1 0 0" type="slide"/>
      <joint pos="0 0 0" axis="0 1 0" type="slide"/>
      <joint pos="0 0 0" axis="0 0 1" type="slide"/>
    </body>
    <body name="cloth_225" pos="0.65 -0.65 0.1">
      <inertial pos="0 0 0" mass="0.00390625" diaginertia="6.51042e-08 6.51042e-08 6.51042e-08"/>
      <joint pos="0 0 0" axis="1 0 0" type="slide"/>
      <joint pos="0 0 0" axis="0 1 0" type="slide"/>
      <joint pos="0 0 0" axis="0 0 1" type="slide"/>
    </body>
    <body name="cloth_226" pos="0.65 -0.55 0.1">
      <inertial pos="0 0 0" mass="0.00390625" diaginertia="6.51042e-08 6.51042e-08 6.51042e-08"/>
      <joint pos="0 0 0" axis="1 0 0" type="slide"/>
      <joint pos="0 0 0" axis="0 1 0" type="slide"/>
      <joint pos="0 0 0" axis="0 0 1" type="slide"/>
    </body>
    <body name="cloth_227" pos="0.65 -0.45 0.1">
      <inertial pos="0 0 0" mass="0.00390625" diaginertia="6.51042e-08 6.51042e-08 6.51042e-08"/>
      <joint pos="0 0 0" axis="1 0 0" type="slide"/>
      <joint pos="0 0 0" axis="0 1 0" type="slide"/>
      <joint pos="0 0 0" axis="0 0 1" type="slide"/>
    </body>
    <body name="cloth_228" pos="0.65 -0.35 0.1">
      <inertial pos="0 0 0" mass="0.00390625" diaginertia="6.51042e-08 6.51042e-08 6.51042e-08"/>
      <joint pos="0 0 0" axis="1 0 0" type="slide"/>
      <joint pos="0 0 0" axis="0 1 0" type="slide"/>
      <joint pos="0 0 0" axis="0 0 1" type="slide"/>
    </body>
    <body name="cloth_229" pos="0.65 -0.25 0.1">
      <inertial pos="0 0 0" mass="0.00390625" diaginertia="6.51042e-08 6.51042e-08 6.51042e-08"/>
      <joint pos="0 0 0" axis="1 0 0" type="slide"/>
      <joint pos="0 0 0" axis="0 1 0" type="slide"/>
      <joint pos="0 0 0" axis="0 0 1" type="slide"/>
    </body>
    <body name="cloth_230" pos="0.65 -0.15 0.1">
      <inertial pos="0 0 0" mass="0.00390625" diaginertia="6.51042e-08 6.51042e-08 6.51042e-08"/>
      <joint pos="0 0 0" axis="1 0 0" type="slide"/>
      <joint pos="0 0 0" axis="0 1 0" type="slide"/>
      <joint pos="0 0 0" axis="0 0 1" type="slide"/>
    </body>
    <body name="cloth_231" pos="0.65 -0.05 0.1">
      <inertial pos="0 0 0" mass="0.00390625" diaginertia="6.51042e-08 6.51042e-08 6.51042e-08"/>
      <joint pos="0 0 0" axis="1 0 0" type="slide"/>
      <joint pos="0 0 0" axis="0 1 0" type="slide"/>
      <joint pos="0 0 0" axis="0 0 1" type="slide"/>
    </body>
    <body name="cloth_232" pos="0.65 0.05 0.1">
      <inertial pos="0 0 0" mass="0.00390625" diaginertia="6.51042e-08 6.51042e-08 6.51042e-08"/>
      <joint pos="0 0 0" axis="1 0 0" type="slide"/>
      <joint pos="0 0 0" axis="0 1 0" type="slide"/>
      <joint pos="0 0 0" axis="0 0 1" type="slide"/>
    </body>
    <body name="cloth_233" pos="0.65 0.15 0.1">
      <inertial pos="0 0 0" mass="0.00390625" diaginertia="6.51042e-08 6.51042e-08 6.51042e-08"/>
      <joint pos="0 0 0" axis="1 0 0" type="slide"/>
      <joint pos="0 0 0" axis="0 1 0" type="slide"/>
      <joint pos="0 0 0" axis="0 0 1" type="slide"/>
    </body>
    <body name="cloth_234" pos="0.65 0.25 0.1">
      <inertial pos="0 0 0" mass="0.00390625" diaginertia="6.51042e-08 6.51042e-08 6.51042e-08"/>
      <joint pos="0 0 0" axis="1 0 0" type="slide"/>
      <joint pos="0 0 0" axis="0 1 0" type="slide"/>
      <joint pos="0 0 0" axis="0 0 1" type="slide"/>
    </body>
    <body name="cloth_235" pos="0.65 0.35 0.1">
      <inertial pos="0 0 0" mass="0.00390625" diaginertia="6.51042e-08 6.51042e-08 6.51042e-08"/>
      <joint pos="0 0 0" axis="1 0 0" type="slide"/>
      <joint pos="0 0 0" axis="0 1 0" type="slide"/>
      <joint pos="0 0 0" axis="0 0 1" type="slide"/>
    </body>
    <body name="cloth_236" pos="0.65 0.45 0.1">
      <inertial pos="0 0 0" mass="0.00390625" diaginertia="6.51042e-08 6.51042e-08 6.51042e-08"/>
      <joint pos="0 0 0" axis="1 0 0" type="slide"/>
      <joint pos="0 0 0" axis="0 1 0" type="slide"/>
      <joint pos="0 0 0" axis="0 0 1" type="slide"/>
    </body>
    <body name="cloth_237" pos="0.65 0.55 0.1">
      <inertial pos="0 0 0" mass="0.00390625" diaginertia="6.51042e-08 6.51042e-08 6.51042e-08"/>
      <joint pos="0 0 0" axis="1 0 0" type="slide"/>
      <joint pos="0 0 0" axis="0 1 0" type="slide"/>
      <joint pos="0 0 0" axis="0 0 1" type="slide"/>
    </body>
    <body name="cloth_238" pos="0.65 0.65 0.1">
      <inertial pos="0 0 0" mass="0.00390625" diaginertia="6.51042e-08 6.51042e-08 6.51042e-08"/>
      <joint pos="0 0 0" axis="1 0 0" type="slide"/>
      <joint pos="0 0 0" axis="0 1 0" type="slide"/>
      <joint pos="0 0 0" axis="0 0 1" type="slide"/>
    </body>
    <body name="cloth_239" pos="0.65 0.75 0.1">
      <inertial pos="0 0 0" mass="0.00390625" diaginertia="6.51042e-08 6.51042e-08 6.51042e-08"/>
      <joint pos="0 0 0" axis="1 0 0" type="slide"/>
      <joint pos="0 0 0" axis="0 1 0" type="slide"/>
      <joint pos="0 0 0" axis="0 0 1" type="slide"/>
    </body>
    <body name="cloth_240" pos="0.75 -0.75 0.1">
      <inertial pos="0 0 0" mass="0.00390625" diaginertia="6.51042e-08 6.51042e-08 6.51042e-08"/>
      <joint pos="0 0 0" axis="1 0 0" type="slide"/>
      <joint pos="0 0 0" axis="0 1 0" type="slide"/>
      <joint pos="0 0 0" axis="0 0 1" type="slide"/>
    </body>
    <body name="cloth_241" pos="0.75 -0.65 0.1">
      <inertial pos="0 0 0" mass="0.00390625" diaginertia="6.51042e-08 6.51042e-08 6.51042e-08"/>
      <joint pos="0 0 0" axis="1 0 0" type="slide"/>
      <joint pos="0 0 0" axis="0 1 0" type="slide"/>
      <joint pos="0 0 0" axis="0 0 1" type="slide"/>
    </body>
    <body name="cloth_242" pos="0.75 -0.55 0.1">
      <inertial pos="0 0 0" mass="0.00390625" diaginertia="6.51042e-08 6.51042e-08 6.51042e-08"/>
      <joint pos="0 0 0" axis="1 0 0" type="slide"/>
      <joint pos="0 0 0" axis="0 1 0" type="slide"/>
      <joint pos="0 0 0" axis="0 0 1" type="slide"/>
    </body>
    <body name="cloth_243" pos="0.75 -0.45 0.1">
      <inertial pos="0 0 0" mass="0.00390625" diaginertia="6.51042e-08 6.51042e-08 6.51042e-08"/>
      <joint pos="0 0 0" axis="1 0 0" type="slide"/>
      <joint pos="0 0 0" axis="0 1 0" type="slide"/>
      <joint pos="0 0 0" axis="0 0 1" type="slide"/>
    </body>
    <body name="cloth_244" pos="0.75 -0.35 0.1">
      <inertial pos="0 0 0" mass="0.00390625" diaginertia="6.51042e-08 6.51042e-08 6.51042e-08"/>
      <joint pos="0 0 0" axis="1 0 0" type="slide"/>
      <joint pos="0 0 0" axis="0 1 0" type="slide"/>
      <joint pos="0 0 0" axis="0 0 1" type="slide"/>
    </body>
    <body name="cloth_245" pos="0.75 -0.25 0.1">
      <inertial pos="0 0 0" mass="0.00390625" diaginertia="6.51042e-08 6.51042e-08 6.51042e-08"/>
      <joint pos="0 0 0" axis="1 0 0" type="slide"/>
      <joint pos="0 0 0" axis="0 1 0" type="slide"/>
      <joint pos="0 0 0" axis="0 0 1" type="slide"/>
    </body>
    <body name="cloth_246" pos="0.75 -0.15 0.1">
      <inertial pos="0 0 0" mass="0.00390625" diaginertia="6.51042e-08 6.51042e-08 6.51042e-08"/>
      <joint pos="0 0 0" axis="1 0 0" type="slide"/>
      <joint pos="0 0 0" axis="0 1 0" type="slide"/>
      <joint pos="0 0 0" axis="0 0 1" type="slide"/>
    </body>
    <body name="cloth_247" pos="0.75 -0.05 0.1">
      <inertial pos="0 0 0" mass="0.00390625" diaginertia="6.51042e-08 6.51042e-08 6.51042e-08"/>
      <joint pos="0 0 0" axis="1 0 0" type="slide"/>
      <joint pos="0 0 0" axis="0 1 0" type="slide"/>
      <joint pos="0 0 0" axis="0 0 1" type="slide"/>
    </body>
    <body name="cloth_248" pos="0.75 0.05 0.1">
      <inertial pos="0 0 0" mass="0.00390625" diaginertia="6.51042e-08 6.51042e-08 6.51042e-08"/>
      <joint pos="0 0 0" axis="1 0 0" type="slide"/>
      <joint pos="0 0 0" axis="0 1 0" type="slide"/>
      <joint pos="0 0 0" axis="0 0 1" type="slide"/>
    </body>
    <body name="cloth_249" pos="0.75 0.15 0.1">
      <inertial pos="0 0 0" mass="0.00390625" diaginertia="6.51042e-08 6.51042e-08 6.51042e-08"/>
      <joint pos="0 0 0" axis="1 0 0" type="slide"/>
      <joint pos="0 0 0" axis="0 1 0" type="slide"/>
      <joint pos="0 0 0" axis="0 0 1" type="slide"/>
    </body>
    <body name="cloth_250" pos="0.75 0.25 0.1">
      <inertial pos="0 0 0" mass="0.00390625" diaginertia="6.51042e-08 6.51042e-08 6.51042e-08"/>
      <joint pos="0 0 0" axis="1 0 0" type="slide"/>
      <joint pos="0 0 0" axis="0 1 0" type="slide"/>
      <joint pos="0 0 0" axis="0 0 1" type="slide"/>
    </body>
    <body name="cloth_251" pos="0.75 0.35 0.1">
      <inertial pos="0 0 0" mass="0.00390625" diaginertia="6.51042e-08 6.51042e-08 6.51042e-08"/>
      <joint pos="0 0 0" axis="1 0 0" type="slide"/>
      <joint pos="0 0 0" axis="0 1 0" type="slide"/>
      <joint pos="0 0 0" axis="0 0 1" type="slide"/>
    </body>
    <body name="cloth_252" pos="0.75 0.45 0.1">
      <inertial pos="0 0 0" mass="0.00390625" diaginertia="6.51042e-08 6.51042e-08 6.51042e-08"/>
      <joint pos="0 0 0" axis="1 0 0" type="slide"/>
      <joint pos="0 0 0" axis="0 1 0" type="slide"/>
      <joint pos="0 0 0" axis="0 0 1" type="slide"/>
    </body>
    <body name="cloth_253" pos="0.75 0.55 0.1">
      <inertial pos="0 0 0" mass="0.00390625" diaginertia="6.51042e-08 6.51042e-08 6.51042e-08"/>
      <joint pos="0 0 0" axis="1 0 0" type="slide"/>
      <joint pos="0 0 0" axis="0 1 0" type="slide"/>
      <joint pos="0 0 0" axis="0 0 1" type="slide"/>
    </body>
    <body name="cloth_254" pos="0.75 0.65 0.1">
      <inertial pos="0 0 0" mass="0.00390625" diaginertia="6.51042e-08 6.51042e-08 6.51042e-08"/>
      <joint pos="0 0 0" axis="1 0 0" type="slide"/>
      <joint pos="0 0 0" axis="0 1 0" type="slide"/>
      <joint pos="0 0 0" axis="0 0 1" type="slide"/>
    </body>
    <body name="cloth_255" pos="0.75 0.75 0.1">
      <inertial pos="0 0 0" mass="0.00390625" diaginertia="6.51042e-08 6.51042e-08 6.51042e-08"/>
      <joint pos="0 0 0" axis="1 0 0" type="slide"/>
      <joint pos="0 0 0" axis="0 1 0" type="slide"/>
      <joint pos="0 0 0" axis="0 0 1" type="slide"/>
    </body>
  </worldbody>

  <deformable>
    <flex name="cloth" radius="0.001" body="cloth_0 cloth_1 cloth_2 cloth_3 cloth_4 cloth_5 cloth_6 cloth_7 cloth_8 cloth_9 cloth_10 cloth_11 cloth_12 cloth_13 cloth_14 cloth_15 cloth_16 cloth_17 cloth_18 cloth_19 cloth_20 cloth_21 cloth_22 cloth_23 cloth_24 cloth_25 cloth_26 cloth_27 cloth_28 cloth_29 cloth_30 cloth_31 cloth_32 cloth_33 cloth_34 cloth_35 cloth_36 cloth_37 cloth_38 cloth_39 cloth_40 cloth_41 cloth_42 cloth_43 cloth_44 cloth_45 cloth_46 cloth_47 cloth_48 cloth_49 cloth_50 cloth_51 cloth_52 cloth_53 cloth_54 cloth_55 cloth_56 cloth_57 cloth_58 cloth_59 cloth_60 cloth_61 cloth_62 cloth_63 cloth_64 cloth_65 cloth_66 cloth_67 cloth_68 cloth_69 cloth_70 cloth_71 cloth_72 cloth_73 cloth_74 cloth_75 cloth_76 cloth_77 cloth_78 cloth_79 cloth_80 cloth_81 cloth_82 cloth_83 cloth_84 cloth_85 cloth_86 cloth_87 cloth_88 cloth_89 cloth_90 cloth_91 cloth_92 cloth_93 cloth_94 cloth_95 cloth_96 cloth_97 cloth_98 cloth_99 cloth_100 cloth_101 cloth_102 cloth_103 cloth_104 cloth_105 cloth_106 cloth_107 cloth_108 cloth_109 cloth_110 cloth_111 cloth_112 cloth_113 cloth_114 cloth_115 cloth_116 cloth_117 cloth_118 cloth_119 cloth_120 cloth_121 cloth_122 cloth_123 cloth_124 cloth_125 cloth_126 cloth_127 cloth_128 cloth_129 cloth_130 cloth_131 cloth_132 cloth_133 cloth_134 cloth_135 cloth_136 cloth_137 cloth_138 cloth_139 cloth_140 cloth_141 cloth_142 cloth_143 cloth_144 cloth_145 cloth_146 cloth_147 cloth_148 cloth_149 cloth_150 cloth_151 cloth_152 cloth_153 cloth_154 cloth_155 cloth_156 cloth_157 cloth_158 cloth_159 cloth_160 cloth_161 cloth_162 cloth_163 cloth_164 cloth_165 cloth_166 cloth_167 cloth_168 cloth_169 cloth_170 cloth_171 cloth_172 cloth_173 cloth_174 cloth_175 cloth_176 cloth_177 cloth_178 cloth_179 cloth_180 cloth_181 cloth_182 cloth_183 cloth_184 cloth_185 cloth_186 cloth_187 cloth_188 cloth_189 cloth_190 cloth_191 cloth_192 cloth_193 cloth_194 cloth_195 cloth_196 cloth_197 cloth_198 cloth_199 cloth_200 cloth_201 cloth_202 cloth_203 cloth_204 cloth_205 cloth_206 cloth_207 cloth_208 cloth_209 cloth_210 cloth_211 cloth_212 cloth_213 cloth_214 cloth_215 cloth_216 cloth_217 cloth_218 cloth_219 cloth_220 cloth_221 cloth_222 cloth_223 cloth_224 cloth_225 cloth_226 cloth_227 cloth_228 cloth_229 cloth_230 cloth_231 cloth_232 cloth_233 cloth_234 cloth_235 cloth_236 cloth_237 cloth_238 cloth_239 cloth_240 cloth_241 cloth_242 cloth_243 cloth_244 cloth_245 cloth_246 cloth_247 cloth_248 cloth_249 cloth_250 cloth_251 cloth_252 cloth_253 cloth_254 cloth_255" element="0 16 17 0 17 1 1 17 18 1 18 2 2 18 19 2 19 3 3 19 20 3 20 4 4 20 21 4 21 5 5 21 22 5 22 6 6 22 23 6 23 7 7 23 24 7 24 8 8 24 25 8 25 9 9 25 26 9 26 10 10 26 27 10 27 11 11 27 28 11 28 12 12 28 29 12 29 13 13 29 30 13 30 14 14 30 31 14 31 15 16 32 33 16 33 17 17 33 34 17 34 18 18 34 35 18 35 19 19 35 36 19 36 20 20 36 37 20 37 21 21 37 38 21 38 22 22 38 39 22 39 23 23 39 40 23 40 24 24 40 41 24 41 25 25 41 42 25 42 26 26 42 43 26 43 27 27 43 44 27 44 28 28 44 45 28 45 29 29 45 46 29 46 30 30 46 47 30 47 31 32 48 49 32 49 33 33 49 50 33 50 34 34 50 51 34 51 35 35 51 52 35 52 36 36 52 53 36 53 37 37 53 54 37 54 38 38 54 55 38 55 39 39 55 56 39 56 40 40 56 57 40 57 41 41 57 58 41 58 42 42 58 59 42 59 43 43 59 60 43 60 44 44 60 61 44 61 45 45 61 62 45 62 46 46 62 63 46 63 47 48 64 65 48 65 49 49 65 66 49 66 50 50 66 67 50 67 51 51 67 68 51 68 52 52 68 69 52 69 53 53 69 70 53 70 54 54 70 71 54 71 55 55 71 72 55 72 56 56 72 73 56 73 57 57 73 74 57 74 58 58 74 75 58 75 59 59 75 76 59 76 60 60 76 77 60 77 61 61 77 78 61 78 62 62 78 79 62 79 63 64 80 81 64 81 65 65 81 82 65 82 66 66 82 83 66 83 67 67 83 84 67 84 68 68 84 85 68 85 69 69 85 86 69 86 70 70 86 87 70 87 71 71 87 88 71 88 72 72 88 89 72 89 73 73 89 90 73 90 74 74 90 91 74 91 75 75 91 92 75 92 76 76 92 93 76 93 77 77 93 94 77 94 78 78 94 95 78 95 79 80 96 97 80 97 81 81 97 98 81 98 82 82 98 99 82 99 83 83 99 100 83 100 84 84 100 101 84 101 85 85 101 102 85 102 86 86 102 103 86 103 87 87 103 104 87 104 88 88 104 105 88 105 89 89 105 106 89 106 90 90 106 107 90 107 91 91 107 108 91 108 92 92 108 109 92 109 93 93 109 110 93 110 94 94 110 111 94 111 95 96 112 113 96 113 97 97 113 114 97 114 98 98 114 115 98 115 99 99 115 116 99 116 100 100 116 117 100 117 101 101 117 118 101 118 102 102 118 119 102 119 103 103 119 120 103 120 104 104 120 121 104 121 105 105 121 122 105 122 106 106 122 123 106 123 107 107 123 124 107 124 108 108 124 125 108 125 109 109 125 126 109 126 110 110 126 127 110 127 111 112 128 129 112 129 113 113 129 130 113 130 114 114 130 131 114 131 115 115 131 132 115 132 116 116 132 133 116 133 117 117 133 134 117 134 118 118 134 135 118 135 119 119 135 136 119 136 120 120 136 137 120 137 121 121 137 138 121 138 122 122 138 139 122 139 123 123 139 140 123 140 124 124 140 141 124 141 125 125 141 142 125 142 126 126 142 143 126 143 127 128 144 145 128 145 129 129 145 146 129 146 130 130 146 147 130 147 131 131 147 148 131 148 132 132 148 149 132 149 133 133 149 150 133 150 134 134 150 151 134 151 135 135 151 152 135 152 136 136 152 153 136 153 137 137 153 154 137 154 138 138 154 155 138 155 139 139 155 156 139 156 140 140 156 157 140 157 141 141 157 158 141 158 142 142 158 159 142 159 143 144 160 161 144 161 145 145 161 162 145 162 146 146 162 163 146 163 147 147 163 164 147 164 148 148 164 165 148 165 149 149 165 166 149 166 150 150 166 167 150 167 151 151 167 168 151 168 152 152 168 169 152 169 153 153 169 170 153 170 154 154 170 171 154 171 155 155 171 172 155 172 156 156 172 173 156 173 157 157 173 174 157 174 158 158 174 175 158 175 159 160 176 177 160 177 161 161 177 178 161 178 162 162 178 179 162 179 163 163 179 180 163 180 164 164 180 181 164 181 165 165 181 182 165 182 166 166 182 183 166 183 167 167 183 184 167 184 168 168 184 185 168 185 169 169 185 186 169 186 170 170 186 187 170 187 171 171 187 188 171 188 172 172 188 189 172 189 173 173 189 190 173 190 174 174 190 191 174 191 175 176 192 193 176 193 177 177 193 194 177 194 178 178 194 195 178 195 179 179 195 196 179 196 180 180 196 197 180 197 181 181 197 198 181 198 182 182 198 199 182 199 183 183 199 200 183 200 184 184 200 201 184 201 185 185 201 202 185 202 186 186 202 203 186 203 187 187 203 204 187 204 188 188 204 205 188 205 189 189 205 206 189 206 190 190 206 207 190 207 191 192 208 209 192 209 193 193 209 210 193 210 194 194 210 211 194 211 195 195 211 212 195 212 196 196 212 213 196 213 197 197 213 214 197 214 198 198 214 215 198 215 199 199 215 216 199 216 200 200 216 217 200 217 201 201 217 218 201 218 202 202 218 219 202 219 203 203 219 220 203 220 204 204 220 221 204 221 205 205 221 222 205 222 206 206 222 223 206 223 207 208 224 225 208 225 209 209 225 226 209 226 210 210 226 227 210 227 211 211 227 228 211 228 212 212 228 229 212 229 213 213 229 230 213 230 214 214 230 231 214 231 215 215 231 232 215 232 216 216 232 233 216 233 217 217 233 234 217 234 218 218 234 235 218 235 219 219 235 236 219 236 220 220 236 237 220 237 221 221 237 238 221 238 222 222 238 239 222 239 223 224 240 241 224 241 225 225 241 242 225 242 226 226 242 243 226 243 227 227 243 244 227 244 228 228 244 245 228 245 229 229 245 246 229 246 230 230 246 247 230 247 231 231 247 248 231 248 232 232 248 249 232 249 233 233 249 250 233 250 234 234 250 251 234 251 235 235 251 252 235 252 236 236 252 253 236 253 237 237 253 254 237 254 238 238 254 255 238 255 239">

      <contact contype="4" conaffinity="65535" solref="0.01 1" solimp="0.95 0.99 0.0001 0.5 2" selfcollide="none"/>
      <elasticity young="100000" thickness="0.01"/>
      <edge damping="2"/>
    </flex>
  </deformable>
</mujoco>
