<mujoco model="ur5e_simplified">
  <compiler angle="radian" meshdir="assets" autolimits="true"/>
  <option integrator="implicitfast"/>

  <default>
    <default class="ur5e">
      <material specular="0.5" shininess="0.25"/>
      <joint axis="0 1 0" range="-6.28319 6.28319" armature="0.1"/>
      <general gaintype="fixed" biastype="affine" ctrlrange="-6.2831 6.2831"
               gainprm="2000" biasprm="0 -2000 -400" forcerange="-150 150"/>
      <default class="size3">
        <default class="size3_limited">
          <joint range="-3.1415 3.1415"/>
          <general ctrlrange="-3.1415 3.1415"/>
        </default>
      </default>
      <default class="size1">
        <general gainprm="500" biasprm="0 -500 -100" forcerange="-28 28"/>
      </default>
      <default class="visual">
        <geom type="capsule" size="0.04 0.2" contype="0" conaffinity="0" group="2"/>
      </default>
      <default class="collision">
        <geom type="capsule" group="3"/>
        <default class="eef_collision">
          <geom type="cylinder"/>
        </default>
      </default>
      <site size="0.001" rgba="0.5 0.5 0.5 0.3" group="0"/>
    </default>
  </default>

  <worldbody>
    <!-- <light name="spotlight_0" mode="targetbodycom" target="wrist_z_link_0" pos="0 -1 2"/> -->
    <body name="base_0" euler="0 0 1.5708" pos="1.0 0 0" childclass="ur5e">
      <inertial mass="4.0" pos="0 0 0" diaginertia="0.004433 0.004433 0.0072"/>
      <geom type="cylinder" size="0.09 0.05" rgba="0.3 0.3 0.3 1"/>
      <body name="shoulder_link_0" pos="0 0 0.163">
        <inertial mass="3.7" pos="0 0 0" diaginertia="0.01027 0.01027 0.00666"/>
        <joint name="shoulder_pan_joint_0" class="size3" axis="0 0 1"/>
        <geom type="capsule" fromto="0 0 0 0 0.138 0" size="0.045"/>
        <body name="upper_arm_link_0" pos="0 0.138 0" quat="1 0 1 0">
          <inertial mass="8.393" pos="0 0 0.2125" diaginertia="0.13389 0.13389 0.0151"/>
          <joint name="shoulder_lift_joint_0" class="size3" axis="0 1 0"/>
          <geom type="capsule" fromto="0 0 0 0 -0.131 0.425" size="0.045"/>
          <body name="forearm_link_0" pos="0 -0.131 0.425">
            <inertial mass="2.275" pos="0 0 0.196" diaginertia="0.03118 0.03118 0.0041"/>
            <joint name="elbow_joint_0" class="size3_limited" axis="0 1 0"/>
            <geom type="capsule" fromto="0 0 0 0 0 0.392" size="0.04"/>
            <body name="wrist_y1_link_0" pos="0 0 0.392" quat="1 0 1 0">
              <inertial mass="1.219" pos="0 0.127 0" diaginertia="0.00256 0.00256 0.00219"/>
              <joint name="wrist_y1_joint_0" class="size1" axis="0 1 0"/>
              <geom type="capsule" fromto="0 0 0 0 0.127 0" size="0.035"/>
              <body name="wrist_z_link_0" pos="0 0.127 0">
                <inertial mass="1.219" pos="0 0 0.1" diaginertia="0.00256 0.00256 0.00219"/>
                <joint name="wrist_z_joint_0" class="size1" axis="0 0 1"/>
                <geom type="capsule" fromto="0 0 0 0 0 0.1" size="0.035"/>
                 <camera name="cam_0" pos="0 0 -0.1" euler="2.0 0 3.1416" fovy="60"/>
                <body name="wrist_y2_link_0" pos="0 0 0.1" euler="0 3.1416 0">
                  <inertial mass="0.1889" pos="0 0.0771683 0" quat="1 0 0 1" diaginertia="0.0001321 0.000099 0.000099"/>
                  <joint name="wrist_y2_joint_0" class="size1" axis="0 1 0"/>
                  <geom type="capsule" fromto="0 0 0 0 0.1 0" size="0.03"/>
                  <site name="attachment_site_0" pos="0 0.15 0" quat="-1 1 0 0" size="0.02" rgba="1 0 0 0.5"/>
                </body>
              </body>
            </body>
          </body>
        </body>
      </body>
    </body>
  </worldbody>

  <actuator>
    <general class="size3" name="shoulder_pan_0" joint="shoulder_pan_joint_0"/>
    <general class="size3" name="shoulder_lift_0" joint="shoulder_lift_joint_0"/>
    <general class="size3_limited" name="elbow_0" joint="elbow_joint_0"/>
    <general class="size1" name="wrist_y1_0" joint="wrist_y1_joint_0"/>
    <general class="size1" name="wrist_z_0" joint="wrist_z_joint_0"/>
    <general class="size1" name="wrist_y2_0" joint="wrist_y2_joint_0"/>
  </actuator>
</mujoco>
